<sdf version='1.6'>
  <model name='biped'>
    <link name='x-prism'>
      <pose frame=''>0 0 0.45 0 -0 0</pose>
      <inertial>
        <pose frame=''>0 0 0 0 -0 0</pose>
        <mass>1</mass>
        <inertia>
          <ixx>0.000166667</ixx>
          <ixy>0</ixy>
          <ixz>0</ixz>
          <iyy>0.000166667</iyy>
          <iyz>0</iyz>
          <izz>0.000166667</izz>
        </inertia>
      </inertial>
      <visual name='x-prism_visual'>
        <pose frame=''>0 0 0 0 -0 0</pose>
        <geometry>
          <box>
            <size>0.001 0.001 0.001</size>
          </box>
        </geometry>
      </visual>
    </link>
    <joint name='planx' type='prismatic'>
      <child>x-prism</child>
      <parent>world</parent>
      <axis>
        <xyz>1 0 0</xyz>
        <limit>
          <lower>-500</lower>
          <upper>500</upper>
          <effort>1000</effort>
          <velocity>100</velocity>
        </limit>
        <dynamics>
          <spring_reference>0</spring_reference>
          <spring_stiffness>0</spring_stiffness>
        </dynamics>
        <use_parent_model_frame>1</use_parent_model_frame>
      </axis>
    </joint>
    <link name='z-prism'>
      <pose frame=''>0 0 0.45 0 -0 0</pose>
      <inertial>
        <pose frame=''>0 0 0 0 -0 0</pose>
        <mass>1</mass>
        <inertia>
          <ixx>0.000166667</ixx>
          <ixy>0</ixy>
          <ixz>0</ixz>
          <iyy>0.000166667</iyy>
          <iyz>0</iyz>
          <izz>0.000166667</izz>
        </inertia>
      </inertial>
      <visual name='z-prism_visual'>
        <pose frame=''>0 0 0 0 -0 0</pose>
        <geometry>
          <box>
            <size>0.001 0.001 0.001</size>
          </box>
        </geometry>
      </visual>
    </link>
    <joint name='planz' type='prismatic'>
      <child>z-prism</child>
      <parent>x-prism</parent>
      <axis>
        <xyz>0 0 1</xyz>
        <limit>
          <lower>-500</lower>
          <upper>500</upper>
          <effort>1000</effort>
          <velocity>100</velocity>
        </limit>
        <dynamics>
          <spring_reference>0</spring_reference>
          <spring_stiffness>0</spring_stiffness>
        </dynamics>
        <use_parent_model_frame>1</use_parent_model_frame>
      </axis>
    </joint>
    <link name='hip'>
      <pose frame=''>0 0 0.45 0 -0 0</pose>
      <inertial>
        <pose frame=''>0 0 0 0 -0 0</pose>
        <mass>2.7</mass>
        <inertia>
          <ixx>0.01911</ixx>
          <ixy>4.177e-05</ixy>
          <ixz>-0.003356</ixz>
          <iyy>0.0245</iyy>
          <iyz>-0.0002039</iyz>
          <izz>0.007141</izz>
        </inertia>
      </inertial>
      <collision name='hip_collision'>
        <pose frame=''>0 0 0 0 -0 0</pose>
        <geometry>
          <box>
            <size>0.165 0.06 0.28</size>
          </box>
        </geometry>
        <surface>
          <contact>
            <ode/>
          </contact>
          <friction>
            <ode/>
          </friction>
        </surface>
      </collision>
      <visual name='hip_visual'>
        <pose frame=''>0 0 0 0 -0 0</pose>
        <geometry>
          <box>
            <size>0.165 0.06 0.28</size>
          </box>
        </geometry>
        <material>
          <script>
            <name>Gazebo/Orange</name>
            <uri>file://media/materials/scripts/gazebo.material</uri>
          </script>
        </material>
      </visual>
      <gravity>1</gravity>
      <velocity_decay/>
    </link>
    <joint name='rev' type='revolute'>
      <child>hip</child>
      <parent>z-prism</parent>
      <axis>
        <xyz>0 1 0</xyz>
        <limit>
          <lower>-1e+16</lower>
          <upper>1e+16</upper>
        </limit>
        <dynamics>
          <spring_reference>0</spring_reference>
          <spring_stiffness>0</spring_stiffness>
        </dynamics>
        <use_parent_model_frame>1</use_parent_model_frame>
      </axis>
    </joint>
    <link name='leg_left_abad'>
      <pose frame=''>0 0 0.45 0 -0 0</pose>
      <inertial>
        <pose frame=''>0 0.075 0 0 -0 0</pose>
        <mass>2</mass>
        <inertia>
          <ixx>0.00168333</ixx>
          <ixy>0</ixy>
          <ixz>0</ixz>
          <iyy>0.0156833</iyy>
          <iyz>0</iyz>
          <izz>0.0140333</izz>
        </inertia>
      </inertial>
      <collision name='leg_left_abad_collision'>
        <pose frame=''>0 0.075 0 0 -0 0</pose>
        <geometry>
          <box>
            <size>0.29 0.01 0.1</size>
          </box>
        </geometry>
        <surface>
          <contact>
            <ode/>
          </contact>
          <friction>
            <ode>
              <mu>0.2</mu>
              <mu2>0.2</mu2>
            </ode>
          </friction>
        </surface>
      </collision>
      <visual name='leg_left_abad_visual'>
        <pose frame=''>0 0.075 0 0 -0 0</pose>
        <geometry>
          <box>
            <size>0.29 0.01 0.1</size>
          </box>
        </geometry>
        <material>
          <script>
            <name>Gazebo/Black</name>
            <uri>file://media/materials/scripts/gazebo.material</uri>
          </script>
        </material>
      </visual>
      <gravity>1</gravity>
      <velocity_decay/>
      <self_collide>1</self_collide>
    </link>
    <joint name='left_abad_joint' type='revolute'>
      <child>leg_left_abad</child>
      <parent>hip</parent>
      <axis>
        <xyz>1 0 0</xyz>
        <limit>
          <lower>-0.5236</lower>
          <upper>0.5236</upper>
          <effort>50</effort>
          <velocity>10000</velocity>
        </limit>
        <dynamics>
          <damping>0</damping>
          <friction>0</friction>
          <spring_reference>0</spring_reference>
          <spring_stiffness>0</spring_stiffness>
        </dynamics>
        <use_parent_model_frame>1</use_parent_model_frame>
      </axis>
    </joint>
    <link name='leg_left_spring_rear'>
      <pose frame=''>0 0.09 0.45 0 0.523599 0</pose>
      <inertial>
        <pose frame=''>0 0.005 0 0 -0 0</pose>
        <mass>0.5</mass>
        <inertia>
          <ixx>0.000420833</ixx>
          <ixy>0</ixy>
          <ixz>0</ixz>
          <iyy>0.000833333</iyy>
          <iyz>0</iyz>
          <izz>0.000420833</izz>
        </inertia>
      </inertial>
      <collision name='leg_left_spring_rear_collision'>
        <pose frame=''>0 0.005 0 0 -0 0</pose>
        <geometry>
          <box>
            <size>0.1 0.01 0.1</size>
          </box>
        </geometry>
        <surface>
          <contact>
            <ode/>
          </contact>
          <friction>
            <ode>
              <mu>0.2</mu>
              <mu2>0.2</mu2>
            </ode>
          </friction>
        </surface>
      </collision>
      <visual name='leg_left_spring_rear_visual'>
        <pose frame=''>0 0.005 0 0 -0 0</pose>
        <geometry>
          <box>
            <size>0.1 0.01 0.1</size>
          </box>
        </geometry>
        <material>
          <script>
            <name>Gazebo/Red</name>
            <uri>file://media/materials/scripts/gazebo.material</uri>
          </script>
        </material>
      </visual>
      <gravity>1</gravity>
      <velocity_decay/>
      <self_collide>1</self_collide>
    </link>
    <joint name='left_spring_rear_joint' type='revolute'>
      <child>leg_left_spring_rear</child>
      <parent>leg_left_abad</parent>
      <axis>
        <xyz>0 1 0</xyz>
        <limit>
          <lower>-3.14</lower>
          <upper>3.14</upper>
          <effort>150</effort>
          <velocity>6.3</velocity>
        </limit>
        <dynamics>
          <damping>0</damping>
          <friction>0</friction>
          <spring_reference>0</spring_reference>
          <spring_stiffness>0</spring_stiffness>
        </dynamics>
        <use_parent_model_frame>1</use_parent_model_frame>
      </axis>
    </joint>
    <link name='leg_left_rear_top'>
      <pose frame=''>0 0.118 0.45 3.14159 -0.523606 -3.14159</pose>
      <inertial>
        <pose frame=''>0 0.009 0.112 0 -0 0</pose>
        <mass>0.08</mass>
        <inertia>
          <ixx>0.000452827</ixx>
          <ixy>0</ixy>
          <ixz>0</ixz>
          <iyy>0.000452827</iyy>
          <iyz>0</iyz>
          <izz>4.32e-06</izz>
        </inertia>
      </inertial>
      <collision name='leg_left_rear_top_collision'>
        <pose frame=''>0 0.009 0.112 0 -0 0</pose>
        <geometry>
          <box>
            <size>0.018 0.018 0.26</size>
          </box>
        </geometry>
        <surface>
          <contact>
            <ode/>
          </contact>
          <friction>
            <ode>
              <mu>0.2</mu>
              <mu2>0.2</mu2>
            </ode>
          </friction>
        </surface>
      </collision>
      <visual name='leg_left_rear_top_visual'>
        <pose frame=''>0 0.009 0.112 0 -0 0</pose>
        <geometry>
          <box>
            <size>0.018 0.018 0.26</size>
          </box>
        </geometry>
        <material>
          <script>
            <name>Gazebo/Red</name>
            <uri>file://media/materials/scripts/gazebo.material</uri>
          </script>
        </material>
      </visual>
      <gravity>1</gravity>
      <velocity_decay/>
      <self_collide>1</self_collide>
    </link>
    <joint name='left_rear_joint' type='revolute'>
      <child>leg_left_rear_top</child>
      <parent>leg_left_spring_rear</parent>
      <axis>
        <xyz>0 1 0</xyz>
        <limit>
          <lower>-1.57</lower>
          <upper>1.57</upper>
          <effort>50</effort>
          <velocity>10000</velocity>
        </limit>
        <dynamics>
          <damping>0.7</damping>
          <friction>0</friction>
          <spring_reference>0</spring_reference>
          <spring_stiffness>0</spring_stiffness>
        </dynamics>
        <use_parent_model_frame>1</use_parent_model_frame>
      </axis>
    </joint>
    <link name='leg_left_rear_bot'>
      <pose frame=''>-0.121002 0.118 0.240423 3.14159 0.523591 3.14159</pose>
      <inertial>
        <pose frame=''>0 -0.009 0.112 0 -0 0</pose>
        <mass>0.08</mass>
        <inertia>
          <ixx>0.000452827</ixx>
          <ixy>0</ixy>
          <ixz>0</ixz>
          <iyy>0.000452827</iyy>
          <iyz>0</iyz>
          <izz>4.32e-06</izz>
        </inertia>
      </inertial>
      <visual name='leg_left_rear_bot_visual'>
        <pose frame=''>0 -0.009 0.112 0 -0 0</pose>
        <geometry>
          <box>
            <size>0.018 0.018 0.26</size>
          </box>
        </geometry>
        <material>
          <script>
            <name>Gazebo/White</name>
            <uri>file://media/materials/scripts/gazebo.material</uri>
          </script>
        </material>
      </visual>
      <gravity>1</gravity>
      <velocity_decay/>
      <self_collide>1</self_collide>
    </link>
    <joint name='left_rear_joint2' type='revolute'>
      <child>leg_left_rear_bot</child>
      <parent>leg_left_rear_top</parent>
      <axis>
        <xyz>0 1 0</xyz>
        <limit>
          <lower>-3</lower>
          <upper>3</upper>
          <effort>50</effort>
          <velocity>10000</velocity>
        </limit>
        <dynamics>
          <damping>0.7</damping>
          <friction>0</friction>
          <spring_reference>0</spring_reference>
          <spring_stiffness>0</spring_stiffness>
        </dynamics>
        <use_parent_model_frame>1</use_parent_model_frame>
      </axis>
    </joint>
    <link name='leg_left_front_bot'>
      <pose frame=''>-0.039003 0.118 0.098394 0 0.523606 0</pose>
      <inertial>
        <pose frame=''>0 0.009 0.112 0 -0 0</pose>
        <mass>0.08</mass>
        <inertia>
          <ixx>0.000452827</ixx>
          <ixy>0</ixy>
          <ixz>0</ixz>
          <iyy>0.000452827</iyy>
          <iyz>0</iyz>
          <izz>4.32e-06</izz>
        </inertia>
      </inertial>
      <visual name='leg_left_front_bot_visual'>
        <pose frame=''>0 0.009 0.112 0 -0 0</pose>
        <geometry>
          <box>
            <size>0.018 0.018 0.26</size>
          </box>
        </geometry>
        <material>
          <script>
            <name>Gazebo/White</name>
            <uri>file://media/materials/scripts/gazebo.material</uri>
          </script>
        </material>
      </visual>
      <gravity>1</gravity>
      <velocity_decay/>
      <self_collide>1</self_collide>
    </link>
    <joint name='left_close_joint' type='revolute'>
      <child>leg_left_front_bot</child>
      <parent>leg_left_rear_bot</parent>
      <axis>
        <xyz>0 1 0</xyz>
        <limit>
          <lower>-1e+16</lower>
          <upper>1e+16</upper>
        </limit>
        <dynamics>
          <damping>0.7</damping>
          <friction>0</friction>
          <spring_reference>0</spring_reference>
          <spring_stiffness>0</spring_stiffness>
        </dynamics>
        <use_parent_model_frame>1</use_parent_model_frame>
      </axis>
    </joint>
    <link name='leg_left_front_top'>
      <pose frame=''>0.081999 0.1 0.307971 0 -0.523591 0</pose>
      <inertial>
        <pose frame=''>0 0.009 0.082 0 -0 0</pose>
        <mass>0.08</mass>
        <inertia>
          <ixx>0.000268827</ixx>
          <ixy>0</ixy>
          <ixz>0</ixz>
          <iyy>0.000348827</iyy>
          <iyz>0</iyz>
          <izz>4.32e-06</izz>
        </inertia>
      </inertial>
      <collision name='leg_left_front_top_collision'>
        <pose frame=''>0 0.009 0.082 0 -0 0</pose>
        <geometry>
          <box>
            <size>0.018 0.018 0.2</size>
          </box>
        </geometry>
        <surface>
          <contact>
            <ode/>
          </contact>
          <friction>
            <ode>
              <mu>0.2</mu>
              <mu2>0.2</mu2>
            </ode>
          </friction>
        </surface>
      </collision>
      <visual name='leg_left_front_top_visual'>
        <pose frame=''>0 0.009 0.082 0 -0 0</pose>
        <geometry>
          <box>
            <size>0.018 0.018 0.2</size>
          </box>
        </geometry>
        <material>
          <script>
            <name>Gazebo/Yellow</name>
            <uri>file://media/materials/scripts/gazebo.material</uri>
          </script>
        </material>
      </visual>
      <gravity>1</gravity>
      <velocity_decay/>
      <self_collide>1</self_collide>
    </link>
    <joint name='left_front_joint2' type='revolute'>
      <child>leg_left_front_top</child>
      <parent>leg_left_front_bot</parent>
      <axis>
        <xyz>0 1 0</xyz>
        <limit>
          <lower>-3</lower>
          <upper>3</upper>
          <effort>50</effort>
          <velocity>10000</velocity>
        </limit>
        <dynamics>
          <damping>0.7</damping>
          <friction>0</friction>
          <spring_reference>0</spring_reference>
          <spring_stiffness>0</spring_stiffness>
        </dynamics>
        <use_parent_model_frame>1</use_parent_model_frame>
      </axis>
    </joint>
    <link name='leg_left_spring_front'>
      <pose frame=''>-0 0.08 0.45 3.14159 0.523584 3.14159</pose>
      <inertial>
        <pose frame=''>0 0.005 0 0 -0 0</pose>
        <mass>0.5</mass>
        <inertia>
          <ixx>0.000420833</ixx>
          <ixy>0</ixy>
          <ixz>0</ixz>
          <iyy>0.000833333</iyy>
          <iyz>0</iyz>
          <izz>0.000420833</izz>
        </inertia>
      </inertial>
      <collision name='leg_left_spring_front_collision'>
        <pose frame=''>0 0.005 0 0 -0 0</pose>
        <geometry>
          <box>
            <size>0.1 0.01 0.1</size>
          </box>
        </geometry>
        <surface>
          <contact>
            <ode/>
          </contact>
          <friction>
            <ode>
              <mu>0.2</mu>
              <mu2>0.2</mu2>
            </ode>
          </friction>
        </surface>
      </collision>
      <visual name='leg_left_spring_front_visual'>
        <pose frame=''>0 0.005 0 0 -0 0</pose>
        <geometry>
          <box>
            <size>0.1 0.01 0.1</size>
          </box>
        </geometry>
        <material>
          <script>
            <name>Gazebo/Yellow</name>
            <uri>file://media/materials/scripts/gazebo.material</uri>
          </script>
        </material>
      </visual>
      <gravity>1</gravity>
      <velocity_decay/>
      <self_collide>1</self_collide>
    </link>
    <joint name='left_front_joint' type='revolute'>
      <child>leg_left_spring_front</child>
      <parent>leg_left_front_top</parent>
      <axis>
        <xyz>0 1 0</xyz>
        <limit>
          <lower>-1.57</lower>
          <upper>1.57</upper>
          <effort>50</effort>
          <velocity>10000</velocity>
        </limit>
        <dynamics>
          <damping>0.7</damping>
          <friction>0</friction>
          <spring_reference>0</spring_reference>
          <spring_stiffness>0</spring_stiffness>
        </dynamics>
        <use_parent_model_frame>1</use_parent_model_frame>
      </axis>
    </joint>
    <link name='left_end_tip'>
      <pose frame=''>-3e-06 0.109 0.030844 3.14159 0.523591 3.14159</pose>
      <inertial>
        <pose frame=''>0 0 0 3.14159 1.57079 3.14159</pose>
        <mass>0.02</mass>
        <inertia>
          <ixx>1.72067e-05</ixx>
          <ixy>0</ixy>
          <ixz>0</ixz>
          <iyy>1.68017e-05</iyy>
          <iyz>0</iyz>
          <izz>6.75e-07</izz>
        </inertia>
      </inertial>
      <collision name='left_end_tip_collision'>
        <pose frame=''>0 0 0 3.14159 1.57079 3.14159</pose>
        <geometry>
          <box>
            <size>0.009 0.018 0.1</size>
          </box>
        </geometry>
        <surface>
          <contact>
            <ode/>
          </contact>
          <friction>
            <ode>
              <mu>inf</mu>
              <mu2>inf</mu2>
            </ode>
          </friction>
        </surface>
      </collision>
      <visual name='left_end_tip_visual'>
        <pose frame=''>0 0 0 3.14159 1.57079 3.14159</pose>
        <geometry>
          <box>
            <size>0.009 0.018 0.1</size>
          </box>
        </geometry>
        <material>
          <script>
            <name>Gazebo/Blue</name>
            <uri>file://media/materials/scripts/gazebo.material</uri>
          </script>
        </material>
      </visual>
      <gravity>1</gravity>
      <velocity_decay/>
      <self_collide>1</self_collide>
    </link>
    <joint name='left_end_joint' type='revolute'>
      <child>left_end_tip</child>
      <parent>leg_left_rear_bot</parent>
      <axis>
        <xyz>0 1 0</xyz>
        <limit>
          <lower>-1e+16</lower>
          <upper>1e+16</upper>
        </limit>
        <dynamics>
          <damping>0</damping>
          <friction>0.1</friction>
          <spring_reference>0</spring_reference>
          <spring_stiffness>0</spring_stiffness>
        </dynamics>
        <use_parent_model_frame>1</use_parent_model_frame>
      </axis>
    </joint>
    <link name='leg_right_abad'>
      <pose frame=''>0 0 0.45 0 -0 0</pose>
      <inertial>
        <pose frame=''>0 -0.075 0 0 -0 0</pose>
        <mass>2</mass>
        <inertia>
          <ixx>0.00168333</ixx>
          <ixy>0</ixy>
          <ixz>0</ixz>
          <iyy>0.0156833</iyy>
          <iyz>0</iyz>
          <izz>0.0140333</izz>
        </inertia>
      </inertial>
      <collision name='leg_right_abad_collision'>
        <pose frame=''>0 -0.075 0 0 -0 0</pose>
        <geometry>
          <box>
            <size>0.29 0.01 0.1</size>
          </box>
        </geometry>
        <surface>
          <contact>
            <ode/>
          </contact>
          <friction>
            <ode>
              <mu>0.2</mu>
              <mu2>0.2</mu2>
            </ode>
          </friction>
        </surface>
      </collision>
      <visual name='leg_right_abad_visual'>
        <pose frame=''>0 -0.075 0 0 -0 0</pose>
        <geometry>
          <box>
            <size>0.29 0.01 0.1</size>
          </box>
        </geometry>
        <material>
          <script>
            <name>Gazebo/Black</name>
            <uri>file://media/materials/scripts/gazebo.material</uri>
          </script>
        </material>
      </visual>
      <gravity>1</gravity>
      <velocity_decay/>
      <self_collide>1</self_collide>
    </link>
    <joint name='right_abad_joint' type='revolute'>
      <child>leg_right_abad</child>
      <parent>hip</parent>
      <axis>
        <xyz>1 0 0</xyz>
        <limit>
          <lower>-0.5236</lower>
          <upper>0.5236</upper>
          <effort>50</effort>
          <velocity>10000</velocity>
        </limit>
        <dynamics>
          <damping>0</damping>
          <friction>0</friction>
          <spring_reference>0</spring_reference>
          <spring_stiffness>0</spring_stiffness>
        </dynamics>
        <use_parent_model_frame>1</use_parent_model_frame>
      </axis>
    </joint>
    <link name='leg_right_spring_rear'>
      <pose frame=''>0 -0.09 0.45 0 0.523599 0</pose>
      <inertial>
        <pose frame=''>0 -0.005 0 0 -0 0</pose>
        <mass>0.5</mass>
        <inertia>
          <ixx>0.000420833</ixx>
          <ixy>0</ixy>
          <ixz>0</ixz>
          <iyy>0.000833333</iyy>
          <iyz>0</iyz>
          <izz>0.000420833</izz>
        </inertia>
      </inertial>
      <collision name='leg_right_spring_rear_collision'>
        <pose frame=''>0 -0.005 0 0 -0 0</pose>
        <geometry>
          <box>
            <size>0.1 0.01 0.1</size>
          </box>
        </geometry>
      </collision>
      <visual name='leg_right_spring_rear_visual'>
        <pose frame=''>0 -0.005 0 0 -0 0</pose>
        <geometry>
          <box>
            <size>0.1 0.01 0.1</size>
          </box>
        </geometry>
      </visual>
    </link>
    <joint name='right_spring_rear_joint' type='revolute'>
      <child>leg_right_spring_rear</child>
      <parent>leg_right_abad</parent>
      <axis>
        <xyz>0 1 0</xyz>
        <limit>
          <lower>-3.14</lower>
          <upper>3.14</upper>
          <effort>150</effort>
          <velocity>6.3</velocity>
        </limit>
        <dynamics>
          <damping>0</damping>
          <friction>0</friction>
          <spring_reference>0</spring_reference>
          <spring_stiffness>0</spring_stiffness>
        </dynamics>
        <use_parent_model_frame>1</use_parent_model_frame>
      </axis>
    </joint>
    <link name='leg_right_rear_top'>
      <pose frame=''>0 -0.118 0.45 3.14159 -0.523606 -3.14159</pose>
      <inertial>
        <pose frame=''>0 -0.009 0.112 0 -0 0</pose>
        <mass>0.08</mass>
        <inertia>
          <ixx>0.000452827</ixx>
          <ixy>0</ixy>
          <ixz>0</ixz>
          <iyy>0.000452827</iyy>
          <iyz>0</iyz>
          <izz>4.32e-06</izz>
        </inertia>
      </inertial>
      <collision name='leg_right_rear_top_collision'>
        <pose frame=''>0 -0.009 0.112 0 -0 0</pose>
        <geometry>
          <box>
            <size>0.018 0.018 0.26</size>
          </box>
        </geometry>
        <surface>
          <contact>
            <ode/>
          </contact>
          <friction>
            <ode>
              <mu>0.2</mu>
              <mu2>0.2</mu2>
            </ode>
          </friction>
        </surface>
      </collision>
      <visual name='leg_right_rear_top_visual'>
        <pose frame=''>0 -0.009 0.112 0 -0 0</pose>
        <geometry>
          <box>
            <size>0.018 0.018 0.26</size>
          </box>
        </geometry>
        <material>
          <script>
            <name>Gazebo/White</name>
            <uri>file://media/materials/scripts/gazebo.material</uri>
          </script>
        </material>
      </visual>
      <gravity>1</gravity>
      <velocity_decay/>
      <self_collide>1</self_collide>
    </link>
    <joint name='right_rear_joint' type='revolute'>
      <child>leg_right_rear_top</child>
      <parent>leg_right_spring_rear</parent>
      <axis>
        <xyz>0 1 0</xyz>
        <limit>
          <lower>-1.57</lower>
          <upper>1.57</upper>
          <effort>50</effort>
          <velocity>10000</velocity>
        </limit>
        <dynamics>
          <damping>0.7</damping>
          <friction>0</friction>
          <spring_reference>0</spring_reference>
          <spring_stiffness>0</spring_stiffness>
        </dynamics>
        <use_parent_model_frame>1</use_parent_model_frame>
      </axis>
    </joint>
    <link name='leg_right_rear_bot'>
      <pose frame=''>-0.121002 -0.118 0.240423 3.14159 0.523591 3.14159</pose>
      <inertial>
        <pose frame=''>0 0.009 0.112 0 -0 0</pose>
        <mass>0.08</mass>
        <inertia>
          <ixx>0.000452827</ixx>
          <ixy>0</ixy>
          <ixz>0</ixz>
          <iyy>0.000452827</iyy>
          <iyz>0</iyz>
          <izz>4.32e-06</izz>
        </inertia>
      </inertial>
      <visual name='leg_right_rear_bot_visual'>
        <pose frame=''>0 0.009 0.112 0 -0 0</pose>
        <geometry>
          <box>
            <size>0.018 0.018 0.26</size>
          </box>
        </geometry>
        <material>
          <script>
            <name>Gazebo/White</name>
            <uri>file://media/materials/scripts/gazebo.material</uri>
          </script>
        </material>
      </visual>
      <gravity>1</gravity>
      <velocity_decay/>
      <self_collide>1</self_collide>
    </link>
    <joint name='right_rear_joint2' type='revolute'>
      <child>leg_right_rear_bot</child>
      <parent>leg_right_rear_top</parent>
      <axis>
        <xyz>0 1 0</xyz>
        <limit>
          <lower>-3</lower>
          <upper>3</upper>
          <effort>50</effort>
          <velocity>10000</velocity>
        </limit>
        <dynamics>
          <damping>0.7</damping>
          <friction>0</friction>
          <spring_reference>0</spring_reference>
          <spring_stiffness>0</spring_stiffness>
        </dynamics>
        <use_parent_model_frame>1</use_parent_model_frame>
      </axis>
    </joint>
    <link name='leg_right_front_bot'>
      <pose frame=''>-0.039003 -0.118 0.098394 0 0.523606 0</pose>
      <inertial>
        <pose frame=''>0 -0.009 0.112 0 -0 0</pose>
        <mass>0.08</mass>
        <inertia>
          <ixx>0.000452827</ixx>
          <ixy>0</ixy>
          <ixz>0</ixz>
          <iyy>0.000452827</iyy>
          <iyz>0</iyz>
          <izz>4.32e-06</izz>
        </inertia>
      </inertial>
      <visual name='leg_right_front_bot_visual'>
        <pose frame=''>0 -0.009 0.112 0 -0 0</pose>
        <geometry>
          <box>
            <size>0.018 0.018 0.26</size>
          </box>
        </geometry>
        <material>
          <script>
            <name>Gazebo/White</name>
            <uri>file://media/materials/scripts/gazebo.material</uri>
          </script>
        </material>
      </visual>
      <gravity>1</gravity>
      <velocity_decay/>
      <self_collide>1</self_collide>
    </link>
    <joint name='right_close_joint' type='revolute'>
      <child>leg_right_front_bot</child>
      <parent>leg_right_rear_bot</parent>
      <axis>
        <xyz>0 1 0</xyz>
        <limit>
          <lower>-1e+16</lower>
          <upper>1e+16</upper>
        </limit>
        <dynamics>
          <damping>0.7</damping>
          <friction>0</friction>
          <spring_reference>0</spring_reference>
          <spring_stiffness>0</spring_stiffness>
        </dynamics>
        <use_parent_model_frame>1</use_parent_model_frame>
      </axis>
    </joint>
    <link name='leg_right_front_top'>
      <pose frame=''>0.081999 -0.1 0.307971 0 -0.523591 0</pose>
      <inertial>
        <pose frame=''>0 -0.009 0.082 0 -0 0</pose>
        <mass>0.08</mass>
        <inertia>
          <ixx>0.000268827</ixx>
          <ixy>0</ixy>
          <ixz>0</ixz>
          <iyy>0.000348827</iyy>
          <iyz>0</iyz>
          <izz>4.32e-06</izz>
        </inertia>
      </inertial>
      <collision name='leg_right_front_top_collision'>
        <pose frame=''>0 -0.009 0.082 0 -0 0</pose>
        <geometry>
          <box>
            <size>0.018 0.018 0.2</size>
          </box>
        </geometry>
        <surface>
          <contact>
            <ode/>
          </contact>
          <friction>
            <ode>
              <mu>0.2</mu>
              <mu2>0.2</mu2>
            </ode>
          </friction>
        </surface>
      </collision>
      <visual name='leg_right_front_top_visual'>
        <pose frame=''>0 -0.009 0.082 0 -0 0</pose>
        <geometry>
          <box>
            <size>0.018 0.018 0.2</size>
          </box>
        </geometry>
        <material>
          <script>
            <name>Gazebo/White</name>
            <uri>file://media/materials/scripts/gazebo.material</uri>
          </script>
        </material>
      </visual>
      <gravity>1</gravity>
      <velocity_decay/>
      <self_collide>1</self_collide>
    </link>
    <joint name='right_front_joint2' type='revolute'>
      <child>leg_right_front_top</child>
      <parent>leg_right_front_bot</parent>
      <axis>
        <xyz>0 1 0</xyz>
        <limit>
          <lower>-3</lower>
          <upper>3</upper>
          <effort>50</effort>
          <velocity>10000</velocity>
        </limit>
        <dynamics>
          <damping>0.7</damping>
          <friction>0</friction>
          <spring_reference>0</spring_reference>
          <spring_stiffness>0</spring_stiffness>
        </dynamics>
        <use_parent_model_frame>1</use_parent_model_frame>
      </axis>
    </joint>
    <link name='leg_right_spring_front'>
      <pose frame=''>-0 -0.08 0.45 3.14159 0.523584 3.14159</pose>
      <inertial>
        <pose frame=''>0 -0.005 0 0 -0 0</pose>
        <mass>0.5</mass>
        <inertia>
          <ixx>0.000420833</ixx>
          <ixy>0</ixy>
          <ixz>0</ixz>
          <iyy>0.000833333</iyy>
          <iyz>0</iyz>
          <izz>0.000420833</izz>
        </inertia>
      </inertial>
      <collision name='leg_right_spring_front_collision'>
        <pose frame=''>0 -0.005 0 0 -0 0</pose>
        <geometry>
          <box>
            <size>0.1 0.01 0.1</size>
          </box>
        </geometry>
      </collision>
      <visual name='leg_right_spring_front_visual'>
        <pose frame=''>0 -0.005 0 0 -0 0</pose>
        <geometry>
          <box>
            <size>0.1 0.01 0.1</size>
          </box>
        </geometry>
      </visual>
    </link>
    <joint name='right_front_joint' type='revolute'>
      <child>leg_right_spring_front</child>
      <parent>leg_right_front_top</parent>
      <axis>
        <xyz>0 1 0</xyz>
        <limit>
          <lower>-1.57</lower>
          <upper>1.57</upper>
          <effort>50</effort>
          <velocity>10000</velocity>
        </limit>
        <dynamics>
          <damping>0.7</damping>
          <friction>0</friction>
          <spring_reference>0</spring_reference>
          <spring_stiffness>0</spring_stiffness>
        </dynamics>
        <use_parent_model_frame>1</use_parent_model_frame>
      </axis>
    </joint>
    <link name='right_end_tip'>
      <pose frame=''>-3e-06 -0.109 0.030844 3.14159 0.523591 3.14159</pose>
      <inertial>
        <pose frame=''>0 0 0 3.14159 1.57079 3.14159</pose>
        <mass>0.02</mass>
        <inertia>
          <ixx>1.72067e-05</ixx>
          <ixy>0</ixy>
          <ixz>0</ixz>
          <iyy>1.68017e-05</iyy>
          <iyz>0</iyz>
          <izz>6.75e-07</izz>
        </inertia>
      </inertial>
      <collision name='right_end_tip_collision'>
        <pose frame=''>0 0 0 3.14159 1.57079 3.14159</pose>
        <geometry>
          <box>
            <size>0.009 0.018 0.1</size>
          </box>
        </geometry>
        <surface>
          <contact>
            <ode/>
          </contact>
          <friction>
            <ode>
              <mu>inf</mu>
              <mu2>inf</mu2>
            </ode>
          </friction>
        </surface>
      </collision>
      <visual name='right_end_tip_visual'>
        <pose frame=''>0 0 0 3.14159 1.57079 3.14159</pose>
        <geometry>
          <box>
            <size>0.009 0.018 0.1</size>
          </box>
        </geometry>
        <material>
          <script>
            <name>Gazebo/Blue</name>
            <uri>file://media/materials/scripts/gazebo.material</uri>
          </script>
        </material>
      </visual>
      <gravity>1</gravity>
      <velocity_decay/>
      <self_collide>1</self_collide>
    </link>
    <joint name='right_end_joint' type='revolute'>
      <child>right_end_tip</child>
      <parent>leg_right_rear_bot</parent>
      <axis>
        <xyz>0 1 0</xyz>
        <limit>
          <lower>-1e+16</lower>
          <upper>1e+16</upper>
        </limit>
        <dynamics>
          <damping>0</damping>
          <friction>0.1</friction>
          <spring_reference>0</spring_reference>
          <spring_stiffness>0</spring_stiffness>
        </dynamics>
        <use_parent_model_frame>1</use_parent_model_frame>
      </axis>
    </joint>
    <joint name='right_spring_front_joint' type='revolute'>
      <child>leg_right_abad</child>
      <parent>leg_right_spring_front</parent>
      <axis>
        <xyz>0 1 0</xyz>
        <limit>
          <lower>-3.14</lower>
          <upper>3.14</upper>
          <effort>150</effort>
          <velocity>6.3</velocity>
        </limit>
        <dynamics>
          <damping>0</damping>
          <friction>0</friction>
          <spring_reference>0</spring_reference>
          <spring_stiffness>0</spring_stiffness>
        </dynamics>
        <use_parent_model_frame>1</use_parent_model_frame>
      </axis>
    </joint>
    <joint name='left_spring_front_joint' type='revolute'>
      <child>leg_left_abad</child>
      <parent>leg_left_spring_front</parent>
      <axis>
        <xyz>0 1 0</xyz>
        <limit>
          <lower>-3.14</lower>
          <upper>3.14</upper>
          <effort>150</effort>
          <velocity>6.3</velocity>
        </limit>
        <dynamics>
          <damping>0</damping>
          <friction>0</friction>
          <spring_reference>0</spring_reference>
          <spring_stiffness>0</spring_stiffness>
        </dynamics>
        <use_parent_model_frame>1</use_parent_model_frame>
      </axis>
    </joint>
    <plugin name='gazebo_ros_control' filename='libgazebo_ros_control.so'>
      <robotNamespace>/biped2</robotNamespace>
      <robotSimType>biped2_sim_hardware/BipedHWSim</robotSimType>
    </plugin>
    <plugin name='left_knee_joint_torsional_spring' filename='libgazebo_joint_torsional_spring.so'>
      <kx>143.2394</kx>
      <set_point>0.0</set_point>
      <joint>left_front_joint</joint>
    </plugin>
    <plugin name='left_knee_joint_torsional_spring2' filename='libgazebo_joint_torsional_spring.so'>
      <kx>154.6986</kx>
      <set_point>0.0</set_point>
      <joint>left_rear_joint</joint>
    </plugin>
    <plugin name='right_knee_joint_torsional_spring' filename='libgazebo_joint_torsional_spring.so'>
      <kx>143.2394</kx>
      <set_point>0.0</set_point>
      <joint>right_front_joint</joint>
    </plugin>
    <static>0</static>
    <plugin name='right_knee_joint_torsional_spring2' filename='libgazebo_joint_torsional_spring.so'>
      <kx>154.6986</kx>
      <set_point>0.0</set_point>
      <joint>right_rear_joint</joint>
    </plugin>
  </model>
</sdf>
