<?xml version="1.0" encoding="utf-8"?>
<!-- =================================================================================== -->
<!-- |    This document was autogenerated by xacro from biped.xacro                    | -->
<!-- |    EDITING THIS FILE BY HAND IS NOT RECOMMENDED                                 | -->
<!-- =================================================================================== -->
<robot name="biped">
  <!-- ros_control_plugin -->
  <gazebo>
    <plugin filename="libgazebo_ros_control.so" name="gazebo_ros_control">
      <robotNamespace>/biped2</robotNamespace>
      <!--robotSimType>gazebo_ros_control/DefaultRobotHWSim</robotSimType-->
      <robotSimType>biped2_sim_hardware/BipedHWSim</robotSimType>
    </plugin>
  </gazebo>
  <!--gazebo reference="ground">
    <selfCollide>true</selfCollide>
    <material>Gazebo/Orange</material>
    <robotSimType>gazebo_ros_control/DefaultRobotHWSim</robotSimType>
  </gazebo-->
  <!-- Hip -->
  <gazebo reference="hip">
    <material>Gazebo/Orange</material>
  </gazebo>
  <!-- Spring -->
  <gazebo>
    <plugin filename="libgazebo_joint_torsional_spring.so" name="left_knee_joint_torsional_spring">
      <kx>160</kx>
      <!--set_point>-0.19635</set_point-->
      <set_point>0.0</set_point>
      <joint>left_front_joint</joint>
    </plugin>
  </gazebo>
  <gazebo>
    <plugin filename="libgazebo_joint_torsional_spring.so" name="left_knee_joint_torsional_spring2">
      <kx>160</kx>
      <!--set_point>0.19635</set_point-->
      <set_point>0.0</set_point>
      <joint>left_rear_joint</joint>
    </plugin>
  </gazebo>
  <gazebo>
    <plugin filename="libgazebo_joint_torsional_spring.so" name="right_knee_joint_torsional_spring">
      <kx>160</kx>
      <!--set_point>-0.19635</set_point-->
      <set_point>0.0</set_point>
      <joint>right_front_joint</joint>
    </plugin>
  </gazebo>
  <gazebo>
    <plugin filename="libgazebo_joint_torsional_spring.so" name="right_knee_joint_torsional_spring2">
      <kx>160</kx>
      <!--set_point>0.19635</set_point-->
      <set_point>0.0</set_point>
      <joint>right_rear_joint</joint>
    </plugin>
  </gazebo>
  <!-- Left Leg -->
  <gazebo reference="leg_left_abad">
    <selfCollide>true</selfCollide>
    <mu1>0.2</mu1>
    <mu2>0.2</mu2>
    <material>Gazebo/Black</material>
  </gazebo>
  <!--gazebo reference="left_front_joint">
    <implicitSpringDamper>true</implicitSpringDamper>
    <stopCfm>1.0</stopCfm>
    <stopErp>0.2</stopErp>
    <springStiffness>100</springStiffness>
    <springReference>-0.19635</springReference>
  </gazebo>
  <gazebo reference="left_rear_joint">
    <implicitSpringDamper>true</implicitSpringDamper>
    <stopCfm>1.0</stopCfm>
    <stopErp>0.2</stopErp>
    <springStiffness>100</springStiffness>
    <springReference>0.19635</springReference>
  </gazebo-->
  <gazebo reference="leg_left_front_top">
    <selfCollide>true</selfCollide>
    <mu1>0.2</mu1>
    <mu2>0.2</mu2>
    <material>Gazebo/White</material>
  </gazebo>
  <gazebo reference="leg_left_rear_top">
    <selfCollide>true</selfCollide>
    <mu1>0.2</mu1>
    <mu2>0.2</mu2>
    <material>Gazebo/White</material>
  </gazebo>
  <gazebo reference="leg_left_front_bot">
    <selfCollide>true</selfCollide>
    <mu1>0.2</mu1>
    <mu2>0.2</mu2>
    <material>Gazebo/White</material>
  </gazebo>
  <gazebo reference="leg_left_rear_bot">
    <selfCollide>true</selfCollide>
    <mu1>0.2</mu1>
    <mu2>0.2</mu2>
    <material>Gazebo/White</material>
  </gazebo>
  <gazebo reference="left_end_tip">
    <selfCollide>true</selfCollide>
    <mu1>1</mu1>
    <mu2>1</mu2>
    <material>Gazebo/Blue</material>
  </gazebo>
  <!-- Right Links -->
  <gazebo reference="leg_right_abad">
    <selfCollide>true</selfCollide>
    <mu1>0.2</mu1>
    <mu2>0.2</mu2>
    <material>Gazebo/Black</material>
  </gazebo>
  <gazebo reference="leg_right_front_top">
    <selfCollide>true</selfCollide>
    <mu1>0.2</mu1>
    <mu2>0.2</mu2>
    <material>Gazebo/White</material>
  </gazebo>
  <gazebo reference="leg_right_rear_top">
    <selfCollide>true</selfCollide>
    <mu1>0.2</mu1>
    <mu2>0.2</mu2>
    <material>Gazebo/White</material>
  </gazebo>
  <gazebo reference="leg_right_front_bot">
    <selfCollide>true</selfCollide>
    <mu1>0.2</mu1>
    <mu2>0.2</mu2>
    <material>Gazebo/White</material>
  </gazebo>
  <gazebo reference="leg_right_rear_bot">
    <selfCollide>true</selfCollide>
    <mu1>0.2</mu1>
    <mu2>0.2</mu2>
    <material>Gazebo/White</material>
  </gazebo>
  <gazebo reference="right_end_tip">
    <selfCollide>true</selfCollide>
    <mu1>1</mu1>
    <mu2>1</mu2>
    <material>Gazebo/Blue</material>
  </gazebo>
  <link name="world"/>
  <!--joint name="free" type="floating">
    <parent link="world"/>
    <child link="hip"/>
    <origin xyz="0 0 ${pos_hip}" rpy="0 0 0"/>
  </joint-->
  <!--joint name="fixed" type="fixed">
    <parent link="world"/>
    <child link="hip"/>
    <origin xyz="0 0 ${pos_hip+0.5}" rpy="0 0 0"/>
  </joint-->
  <!--joint name="prism" type="prismatic">
    <parent link="world"/>
    <child link="hip"/>
    <origin xyz="0 0 ${-pos_hip-0.1}" rpy="0 0 0"/>
    <axis xyz="1 0 0"/>
    <limit effort="1000.0" lower="-0.5" upper="1.5" velocity="10.0"/>
  </joint-->
  <!-- Planar joint -->
  <joint name="planx" type="prismatic">
    <parent link="world"/>
    <child link="x-prism"/>
    <origin rpy="0 0 0" xyz="0 0 0.45"/>
    <axis xyz="1 0 0"/>
    <limit effort="1000.0" lower="-10.0" upper="50.0" velocity="10.0"/>
  </joint>
  <link name="x-prism">
    <visual>
      <origin rpy="0 0 0" xyz="0 0 0"/>
      <geometry>
        <box size="0.001 0.001 0.001"/>
      </geometry>
      <material name="orange"/>
    </visual>
    <inertial>
      <origin rpy="0 0 0" xyz="0 0 0"/>
      <mass value="1"/>
      <inertia ixx="0.000166666666667" ixy="0.0" ixz="0.0" iyy="0.000166666666667" iyz="0.0" izz="0.000166666666667"/>
    </inertial>
  </link>
  <joint name="planz" type="prismatic">
    <parent link="x-prism"/>
    <child link="hip"/>
    <axis xyz="0 0 1"/>
    <origin rpy="0 0 0" xyz="0 0 0"/>
    <limit effort="1000.0" lower="-10.0" upper="50.0" velocity="10.0"/>
  </joint>
  <!--link name="z-prism">
    <visual>
      <origin xyz="0 0 0" rpy="0 0 0"/>
      <geometry>
        <box size="0.001 0.001 0.001"/>
      </geometry>
      <material name="orange"/>
    </visual>

    <inertial>
      <origin xyz="0 0 0" rpy="0 0 0"/>
      <mass value="1.0"/>
      <inertia
        ixx="${1.0 / 12.0 * (0.001 + 0.001)}" ixy="0.0" ixz="0.0"
          iyy="${1.0 / 12.0 * (0.001 + 0.001)}" iyz="0.0"
	  izz="${1.0 / 12.0 * (0.001 + 0.001)}" />
    </inertial>
  </link>
  <joint name="rev" type="continuous">
    <parent link="z-prism"/>
    <child link="hip"/>
    <axis xyz="0 1 0"/>
    <origin xyz="0 0 0" rpy="0 0 0"/>
  </joint-->
  <!-- End planar joint -->
  <!-- Hip of the robot -->
  <link name="hip">
    <collision>
      <origin rpy="0 0 0" xyz="0 0 0"/>
      <geometry>
        <box size="0.3 0.15 0.03"/>
      </geometry>
    </collision>
    <visual>
      <origin rpy="0 0 0" xyz="0 0 0"/>
      <geometry>
        <box size="0.3 0.15 0.03"/>
      </geometry>
      <material name="orange"/>
    </visual>
    <inertial>
      <origin rpy="0 0 0" xyz="0 0 0"/>
      <mass value="3"/>
      <inertia ixx="0.00585" ixy="0.0" ixz="0.0" iyy="0.00585" iyz="0.0" izz="0.01125"/>
    </inertial>
  </link>
  <!-- Left abad link -->
  <joint name="left_abad_joint" type="revolute">
    <parent link="hip"/>
    <child link="leg_left_abad"/>
    <origin rpy="0 0 0" xyz="0 0 0"/>
    <axis xyz="1 0 0"/>
    <dynamics damping="0.7"/>
    <limit effort="50.0" lower="-0.5236" upper="0.5236" velocity="10.0"/>
  </joint>
  <link name="leg_left_abad">
    <collision>
      <origin rpy="0 0 0" xyz="0 0.09 0"/>
      <geometry>
        <box size="0.1 0.01 0.1"/>
      </geometry>
    </collision>
    <visual>
      <origin rpy="0 0 0" xyz="0 0.09 0"/>
      <geometry>
        <box size="0.1 0.01 0.1"/>
      </geometry>
      <material name="black"/>
    </visual>
    <inertial>
      <origin rpy="0 0 0" xyz="0 0.09 0"/>
      <mass value="1"/>
      <inertia ixx="0.000841666666667" ixy="0.0" ixz="0.0" iyy="0.00166666666667" iyz="0.0" izz="0.000841666666667"/>
    </inertial>
  </link>
  <!-- Left spring links -->
  <joint name="left_spring_rear_joint" type="continuous">
    <parent link="leg_left_abad"/>
    <child link="leg_left_spring_rear"/>
    <origin rpy="0 0.196 0" xyz="0 0.115 0"/>
    <axis xyz="0 1 0"/>
  </joint>
  <link name="leg_left_spring_rear">
    <collision>
      <origin rpy="0 0 0" xyz="0 0.015 0"/>
      <geometry>
        <box size="0.1 0.01 0.1"/>
      </geometry>
    </collision>
    <visual>
      <origin rpy="0 0 0" xyz="0 0.015 0"/>
      <geometry>
        <box size="0.1 0.01 0.1"/>
      </geometry>
      <material name="black"/>
    </visual>
    <inertial>
      <origin rpy="0 0 0" xyz="0 0.015 0"/>
      <mass value="1"/>
      <inertia ixx="0.000841666666667" ixy="0.0" ixz="0.0" iyy="0.00166666666667" iyz="0.0" izz="0.000841666666667"/>
    </inertial>
  </link>
  <!-- Left leg -->
  <joint name="left_rear_joint" type="revolute">
    <parent link="leg_left_spring_rear"/>
    <child link="leg_left_rear_top"/>
    <origin rpy="0 3.1416 0" xyz="0 0.048 0"/>
    <axis xyz="0 1 0"/>
    <dynamics damping="0.7"/>
    <limit effort="50.0" lower="-1.57" upper="1.57" velocity="10.0"/>
  </joint>
  <!-- Left rear top leg link -->
  <link name="leg_left_rear_top">
    <collision>
      <origin rpy="0 0 0" xyz="0 0.019 0.112"/>
      <geometry>
        <box size="0.018 0.018 0.26"/>
      </geometry>
    </collision>
    <visual>
      <origin rpy="0 0 0" xyz="0 0.001 0.112"/>
      <geometry>
        <box size="0.018 0.018 0.26"/>
      </geometry>
      <material name="black"/>
    </visual>
    <inertial>
      <origin rpy="0 0 0" xyz="0 0.019 0.112"/>
      <mass value="0.15"/>
      <inertia ixx="0.00084905" ixy="0.0" ixz="0.0" iyy="0.00084905" iyz="0.0" izz="8.1e-06"/>
    </inertial>
  </link>
  <joint name="left_rear_joint2" type="revolute">
    <parent link="leg_left_rear_top"/>
    <child link="leg_left_rear_bot"/>
    <!--origin xyz="0 ${space} ${height_rear_top-width_leg}" rpy="0 -1.0472 0"/-->
    <origin rpy="0 -0.393 0" xyz="0 -0.01 0.242"/>
    <axis xyz="0 1 0"/>
    <dynamics damping="0.7"/>
    <limit effort="50.0" lower="-1.57" upper="1.57" velocity="10.0"/>
  </joint>
  <!-- Left rear bottom leg link -->
  <link name="leg_left_rear_bot">
    <collision>
      <origin rpy="0 0 0" xyz="0 0.001 0.112"/>
      <geometry>
        <box size="0.018 0.018 0.26"/>
      </geometry>
    </collision>
    <visual>
      <origin rpy="0 0 0" xyz="0 0.001 0.112"/>
      <geometry>
        <box size="0.018 0.018 0.26"/>
      </geometry>
      <material name="black"/>
    </visual>
    <inertial>
      <origin rpy="0 0 0" xyz="0 0.001 0.112"/>
      <mass value="0.15"/>
      <inertia ixx="0.00084905" ixy="0.0" ixz="0.0" iyy="0.00084905" iyz="0.0" izz="8.1e-06"/>
    </inertial>
  </link>
  <!-- Left closed joint -->
  <joint name="left_close_joint" type="continuous">
    <parent link="leg_left_rear_bot"/>
    <child link="leg_left_front_bot"/>
    <!--origin xyz="0 ${space} ${height_rear_top-width_leg}" rpy="0 -1.0472 0"/-->
    <origin rpy="0 -2.749 0" xyz="0 0.01 0.164"/>
    <axis xyz="0 1 0"/>
    <dynamics damping="0.7"/>
  </joint>
  <!-- Left front bottom leg link -->
  <link name="leg_left_front_bot">
    <!--collision>
      <origin xyz="0 ${width_leg/2+space} ${height_front_bot/2-width_leg}" rpy="0 0 0"/>
      <geometry>
        <box size="${length_leg} ${width_leg} ${height_front_bot}"/>
      </geometry>
    </collision-->
    <visual>
      <origin rpy="0 0 0" xyz="0 0.019 0.112"/>
      <geometry>
        <box size="0.018 0.018 0.26"/>
      </geometry>
      <material name="black"/>
    </visual>
    <inertial>
      <origin rpy="0 0 0" xyz="0 0.019 0.112"/>
      <mass value="0.15"/>
      <inertia ixx="0.00084905" ixy="0.0" ixz="0.0" iyy="0.00084905" iyz="0.0" izz="8.1e-06"/>
    </inertial>
  </link>
  <joint name="left_front_joint2" type="revolute">
    <parent link="leg_left_front_bot"/>
    <child link="leg_left_front_top"/>
    <origin rpy="0 -0.392 0" xyz="0 -0.028 0.242"/>
    <axis xyz="0 1 0"/>
    <dynamics damping="0.7"/>
    <limit effort="50.0" lower="-1.57" upper="1.57" velocity="10.0"/>
  </joint>
  <!-- Left front top leg link -->
  <link name="leg_left_front_top">
    <collision>
      <origin rpy="0 0 0" xyz="0 0.019 0.082"/>
      <geometry>
        <box size="0.018 0.018 0.2"/>
      </geometry>
    </collision>
    <visual>
      <origin rpy="0 0 0" xyz="0 0.019 0.082"/>
      <geometry>
        <box size="0.018 0.018 0.2"/>
      </geometry>
      <material name="black"/>
    </visual>
    <inertial>
      <origin rpy="0 0 0" xyz="0 0.019 0.082"/>
      <mass value="0.15"/>
      <inertia ixx="0.00050405" ixy="0.0" ixz="0.0" iyy="0.00065405" iyz="0.0" izz="8.1e-06"/>
    </inertial>
  </link>
  <joint name="left_front_joint" type="revolute">
    <parent link="leg_left_front_top"/>
    <child link="leg_left_spring_front"/>
    <!--origin xyz="0 ${-height_abad*2-space*2} 0" rpy="0 3.1416 0"/-->
    <origin rpy="0 3.1416 0" xyz="0 -0.04 0.164"/>
    <axis xyz="0 1 0"/>
    <dynamics damping="0.7"/>
    <limit effort="50.0" lower="-1.57" upper="1.57" velocity="10.0"/>
  </joint>
  <!-- Left spring links -->
  <link name="leg_left_spring_front">
    <collision>
      <origin rpy="0 0 0" xyz="0 0.015 0"/>
      <geometry>
        <box size="0.1 0.01 0.1"/>
      </geometry>
    </collision>
    <visual>
      <origin rpy="0 0 0" xyz="0 0.015 0"/>
      <geometry>
        <box size="0.1 0.01 0.1"/>
      </geometry>
      <material name="black"/>
    </visual>
    <inertial>
      <origin rpy="0 0 0" xyz="0 0.015 0"/>
      <mass value="1"/>
      <inertia ixx="0.000841666666667" ixy="0.0" ixz="0.0" iyy="0.00166666666667" iyz="0.0" izz="0.000841666666667"/>
    </inertial>
  </link>
  <!-- Left end joint -->
  <joint name="left_end_joint" type="fixed">
    <origin rpy="0 0 0" xyz="0 0.001 0.242"/>
    <parent link="leg_left_rear_bot"/>
    <child link="left_end_tip"/>
  </joint>
  <link name="left_end_tip">
    <collision>
      <origin rpy="0 0 0" xyz="0 0 0"/>
      <geometry>
        <sphere radius="0.009"/>
      </geometry>
    </collision>
    <visual>
      <origin rpy="0 0 0" xyz="0 0 0"/>
      <geometry>
        <sphere radius="0.009"/>
      </geometry>
      <material name="blue"/>
    </visual>
    <inertial>
      <origin rpy="0 0 0" xyz="0 0 0"/>
      <mass value="0.01"/>
      <inertia ixx="0.0" ixy="0.0" ixz="0.0" iyy="0.0" iyz="0.0" izz="0.0"/>
    </inertial>
  </link>
  <!-- Right leg -->
  <!-- -->
  <!-- -->
  <!-- Right abad link -->
  <joint name="right_abad_joint" type="revolute">
    <parent link="hip"/>
    <child link="leg_right_abad"/>
    <origin rpy="0 0 0" xyz="0 0 0"/>
    <axis xyz="1 0 0"/>
    <dynamics damping="0.7"/>
    <limit effort="50.0" lower="-0.5236" upper="0.5236" velocity="10.0"/>
  </joint>
  <link name="leg_right_abad">
    <collision>
      <origin rpy="0 0 0" xyz="0 -0.09 0"/>
      <geometry>
        <box size="0.1 0.01 0.1"/>
      </geometry>
    </collision>
    <visual>
      <origin rpy="0 0 0" xyz="0 -0.09 0"/>
      <geometry>
        <box size="0.1 0.01 0.1"/>
      </geometry>
      <material name="black"/>
    </visual>
    <inertial>
      <origin rpy="0 0 0" xyz="0 -0.09 0"/>
      <mass value="1"/>
      <inertia ixx="0.000841666666667" ixy="0.0" ixz="0.0" iyy="0.00166666666667" iyz="0.0" izz="0.000841666666667"/>
    </inertial>
  </link>
  <!-- Right spring links -->
  <joint name="right_spring_rear_joint" type="continuous">
    <parent link="leg_right_abad"/>
    <child link="leg_right_spring_rear"/>
    <origin rpy="0 0.196 0" xyz="0 -0.115 0"/>
    <axis xyz="0 1 0"/>
  </joint>
  <link name="leg_right_spring_rear">
    <collision>
      <origin rpy="0 0 0" xyz="0 -0.015 0"/>
      <geometry>
        <box size="0.1 0.01 0.1"/>
      </geometry>
    </collision>
    <visual>
      <origin rpy="0 0 0" xyz="0 -0.015 0"/>
      <geometry>
        <box size="0.1 0.01 0.1"/>
      </geometry>
      <material name="black"/>
    </visual>
    <inertial>
      <origin rpy="0 0 0" xyz="0 -0.015 0"/>
      <mass value="1"/>
      <inertia ixx="0.000841666666667" ixy="0.0" ixz="0.0" iyy="0.00166666666667" iyz="0.0" izz="0.000841666666667"/>
    </inertial>
  </link>
  <!-- Right leg -->
  <joint name="right_rear_joint" type="revolute">
    <parent link="leg_right_spring_rear"/>
    <child link="leg_right_rear_top"/>
    <origin rpy="0 3.1416 0" xyz="0 -0.048 0"/>
    <axis xyz="0 1 0"/>
    <dynamics damping="0.7"/>
    <limit effort="50.0" lower="-1.57" upper="1.57" velocity="10.0"/>
  </joint>
  <!-- right rear top leg link -->
  <link name="leg_right_rear_top">
    <collision>
      <origin rpy="0 0 0" xyz="0 -0.019 0.112"/>
      <geometry>
        <box size="0.018 0.018 0.26"/>
      </geometry>
    </collision>
    <visual>
      <origin rpy="0 0 0" xyz="0 -0.019 0.112"/>
      <geometry>
        <box size="0.018 0.018 0.26"/>
      </geometry>
      <material name="black"/>
    </visual>
    <inertial>
      <origin rpy="0 0 0" xyz="0 -0.019 0.112"/>
      <mass value="0.15"/>
      <inertia ixx="0.00084905" ixy="0.0" ixz="0.0" iyy="0.00084905" iyz="0.0" izz="8.1e-06"/>
    </inertial>
  </link>
  <joint name="right_rear_joint2" type="revolute">
    <parent link="leg_right_rear_top"/>
    <child link="leg_right_rear_bot"/>
    <!--origin xyz="0 ${space} ${height_rear_top-width_leg}" rpy="0 -1.0472 0"/-->
    <origin rpy="0 -0.393 0" xyz="0 0.01 0.242"/>
    <axis xyz="0 1 0"/>
    <dynamics damping="0.7"/>
    <limit effort="50.0" lower="-1.57" upper="1.57" velocity="10.0"/>
  </joint>
  <!-- right rear bottom leg link -->
  <link name="leg_right_rear_bot">
    <!--collision>
      <origin xyz="0 ${width_leg/2-space} ${height_rear_bot/2-width_leg}" rpy="0 0 0"/>
      <geometry>
        <box size="${length_leg} ${width_leg} ${height_rear_bot}"/>
      </geometry>
    </collision-->
    <visual>
      <origin rpy="0 0 0" xyz="0 -0.001 0.112"/>
      <geometry>
        <box size="0.018 0.018 0.26"/>
      </geometry>
      <material name="black"/>
    </visual>
    <inertial>
      <origin rpy="0 0 0" xyz="0 -0.001 0.112"/>
      <mass value="0.15"/>
      <inertia ixx="0.00084905" ixy="0.0" ixz="0.0" iyy="0.00084905" iyz="0.0" izz="8.1e-06"/>
    </inertial>
  </link>
  <!-- Right closed joint -->
  <joint name="right_close_joint" type="continuous">
    <parent link="leg_right_rear_bot"/>
    <child link="leg_right_front_bot"/>
    <!--origin xyz="0 ${space} ${height_rear_top-width_leg}" rpy="0 -1.0472 0"/-->
    <origin rpy="0 -2.749 0" xyz="0 -0.01 0.164"/>
    <axis xyz="0 1 0"/>
    <dynamics damping="0.7"/>
  </joint>
  <!-- right front bottom leg link -->
  <link name="leg_right_front_bot">
    <!--collision>
      <origin xyz="0 ${-width_leg/2-space} ${height_front_bot/2-width_leg}" rpy="0 0 0"/>
      <geometry>
        <box size="${length_leg} ${width_leg} ${height_front_bot}"/>
      </geometry>
    </collision-->
    <visual>
      <origin rpy="0 0 0" xyz="0 -0.019 0.112"/>
      <geometry>
        <box size="0.018 0.018 0.26"/>
      </geometry>
      <material name="black"/>
    </visual>
    <inertial>
      <origin rpy="0 0 0" xyz="0 -0.019 0.112"/>
      <mass value="0.15"/>
      <inertia ixx="0.00084905" ixy="0.0" ixz="0.0" iyy="0.00084905" iyz="0.0" izz="8.1e-06"/>
    </inertial>
  </link>
  <joint name="right_front_joint2" type="revolute">
    <parent link="leg_right_front_bot"/>
    <child link="leg_right_front_top"/>
    <origin rpy="0 -0.392 0" xyz="0 0.028 0.242"/>
    <axis xyz="0 1 0"/>
    <dynamics damping="0.7"/>
    <limit effort="50.0" lower="-1.57" upper="1.57" velocity="10.0"/>
  </joint>
  <!-- Right front top leg link -->
  <link name="leg_right_front_top">
    <collision>
      <origin rpy="0 0 0" xyz="0 -0.019 0.082"/>
      <geometry>
        <box size="0.018 0.018 0.2"/>
      </geometry>
    </collision>
    <visual>
      <origin rpy="0 0 0" xyz="0 -0.019 0.082"/>
      <geometry>
        <box size="0.018 0.018 0.2"/>
      </geometry>
      <material name="black"/>
    </visual>
    <inertial>
      <origin rpy="0 0 0" xyz="0 -0.019 0.082"/>
      <mass value="0.15"/>
      <inertia ixx="0.00050405" ixy="0.0" ixz="0.0" iyy="0.00065405" iyz="0.0" izz="8.1e-06"/>
    </inertial>
  </link>
  <joint name="right_front_joint" type="revolute">
    <parent link="leg_right_front_top"/>
    <child link="leg_right_spring_front"/>
    <!--origin xyz="0 ${-height_abad*2-space*2} 0" rpy="0 3.1416 0"/-->
    <origin rpy="0 3.1416 0" xyz="0 0.04 0.164"/>
    <axis xyz="0 1 0"/>
    <dynamics damping="0.7"/>
    <limit effort="50.0" lower="-1.57" upper="1.57" velocity="10.0"/>
  </joint>
  <!-- Right spring links -->
  <link name="leg_right_spring_front">
    <collision>
      <origin rpy="0 0 0" xyz="0 -0.015 0"/>
      <geometry>
        <box size="0.1 0.01 0.1"/>
      </geometry>
    </collision>
    <visual>
      <origin rpy="0 0 0" xyz="0 -0.015 0"/>
      <geometry>
        <box size="0.1 0.01 0.1"/>
      </geometry>
      <material name="black"/>
    </visual>
    <inertial>
      <origin rpy="0 0 0" xyz="0 -0.015 0"/>
      <mass value="1"/>
      <inertia ixx="0.000841666666667" ixy="0.0" ixz="0.0" iyy="0.00166666666667" iyz="0.0" izz="0.000841666666667"/>
    </inertial>
  </link>
  <!-- Right end joint -->
  <joint name="right_end_joint" type="continuous">
    <origin rpy="0 0 0" xyz="0 -0.001 0.242"/>
    <parent link="leg_right_rear_bot"/>
    <child link="right_end_tip"/>
    <axis xyz="0 1 0"/>
  </joint>
  <link name="right_end_tip">
    <collision>
      <origin rpy="0 1.57079632679 0" xyz="0 0 0.01"/>
      <geometry>
        <box size="0.009 0.018 0.1"/>
      </geometry>
    </collision>
    <visual>
      <origin rpy="0 1.57079632679 0" xyz="0 0 0.01"/>
      <geometry>
        <box size="0.009 0.018 0.1"/>
      </geometry>
      <material name="blue"/>
    </visual>
    <inertial>
      <origin rpy="0 0 0" xyz="0 0 0.1"/>
      <mass value="0.01875"/>
      <inertia ixx="1.613125e-05" ixy="0.0" ixz="0.0" iyy="1.613125e-05" iyz="0.0" izz="1.0125e-06"/>
    </inertial>
  </link>
  <!--joint name="left_spring_front_joint" type="continuous">
    <parent link="leg_left_spring_front"/>
    <child link="leg_left_abad"/>
    <origin xyz="0 ${width_hip/2+height_abad+space} 0" rpy="0 -2.946 0"/>
    <axis xyz="0 1 0"/>
  </joint>
  <joint name="right_spring_front_joint" type="continuous">
    <parent link="leg_right_spring_front"/>
    <child link="leg_right_abad"/>
    <origin xyz="0 ${-width_hip/2-height_abad-space} 0" rpy="0 -2.946 0"/>
    <axis xyz="0 1 0"/>
  </joint-->
  <!-- Define transmission -->
  <!-- Left -->
  <transmission name="left_abad">
    <type>transmission_interface/SimpleTransmission</type>
    <joint name="left_abad_joint">
      <hardwareInterface>hardware_interface/EffortJointInterface</hardwareInterface>
    </joint>
    <actuator name="left_abad_motor">
      <hardwareInterface>hardware_interface/EffortJointInterface</hardwareInterface>
      <mechanicalReduction>1</mechanicalReduction>
    </actuator>
  </transmission>
  <transmission name="left_spring_front">
    <type>transmission_interface/SimpleTransmission</type>
    <joint name="left_spring_front_joint">
      <hardwareInterface>hardware_interface/EffortJointInterface</hardwareInterface>
    </joint>
    <actuator name="left_spring_motor">
      <hardwareInterface>hardware_interface/EffortJointInterface</hardwareInterface>
      <mechanicalReduction>1</mechanicalReduction>
    </actuator>
  </transmission>
  <transmission name="left_spring_rear">
    <type>transmission_interface/SimpleTransmission</type>
    <joint name="left_spring_rear_joint">
      <hardwareInterface>hardware_interface/EffortJointInterface</hardwareInterface>
    </joint>
    <actuator name="left_spring_motor">
      <hardwareInterface>hardware_interface/EffortJointInterface</hardwareInterface>
      <mechanicalReduction>1</mechanicalReduction>
    </actuator>
  </transmission>
  <transmission name="left_rear2">
    <type>transmission_interface/SimpleTransmission</type>
    <joint name="left_rear_joint2">
      <hardwareInterface>hardware_interface/EffortJointInterface</hardwareInterface>
    </joint>
    <actuator name="left_rear_motor2">
      <hardwareInterface>hardware_interface/EffortJointInterface</hardwareInterface>
      <mechanicalReduction>1</mechanicalReduction>
    </actuator>
  </transmission>
  <transmission name="left_front2">
    <type>transmission_interface/SimpleTransmission</type>
    <joint name="left_front_joint2">
      <hardwareInterface>hardware_interface/EffortJointInterface</hardwareInterface>
    </joint>
    <actuator name="left_front_motor2">
      <hardwareInterface>hardware_interface/EffortJointInterface</hardwareInterface>
      <mechanicalReduction>1</mechanicalReduction>
    </actuator>
  </transmission>
  <!-- Right -->
  <transmission name="right_abad">
    <type>transmission_interface/SimpleTransmission</type>
    <joint name="right_abad_joint">
      <hardwareInterface>hardware_interface/EffortJointInterface</hardwareInterface>
    </joint>
    <actuator name="right_abad_motor">
      <hardwareInterface>hardware_interface/EffortJointInterface</hardwareInterface>
      <mechanicalReduction>1</mechanicalReduction>
    </actuator>
  </transmission>
  <transmission name="right_spring_front">
    <type>transmission_interface/SimpleTransmission</type>
    <joint name="right_spring_front_joint">
      <hardwareInterface>hardware_interface/EffortJointInterface</hardwareInterface>
    </joint>
    <actuator name="right_spring_motor">
      <hardwareInterface>hardware_interface/EffortJointInterface</hardwareInterface>
      <mechanicalReduction>1</mechanicalReduction>
    </actuator>
  </transmission>
  <transmission name="right_spring_rear">
    <type>transmission_interface/SimpleTransmission</type>
    <joint name="right_spring_rear_joint">
      <hardwareInterface>hardware_interface/EffortJointInterface</hardwareInterface>
    </joint>
    <actuator name="right_spring_motor">
      <hardwareInterface>hardware_interface/EffortJointInterface</hardwareInterface>
      <mechanicalReduction>1</mechanicalReduction>
    </actuator>
  </transmission>
  <transmission name="right_rear2">
    <type>transmission_interface/SimpleTransmission</type>
    <joint name="right_rear_joint2">
      <hardwareInterface>hardware_interface/EffortJointInterface</hardwareInterface>
    </joint>
    <actuator name="right_rear_motor2">
      <hardwareInterface>hardware_interface/EffortJointInterface</hardwareInterface>
      <mechanicalReduction>1</mechanicalReduction>
    </actuator>
  </transmission>
  <transmission name="right_front2">
    <type>transmission_interface/SimpleTransmission</type>
    <joint name="right_front_joint2">
      <hardwareInterface>hardware_interface/EffortJointInterface</hardwareInterface>
    </joint>
    <actuator name="right_front_motor2">
      <hardwareInterface>hardware_interface/EffortJointInterface</hardwareInterface>
      <mechanicalReduction>1</mechanicalReduction>
    </actuator>
  </transmission>
  <!-- Closed loop joint -->
  <transmission name="right_close">
    <type>transmission_interface/SimpleTransmission</type>
    <joint name="right_close_joint">
      <hardwareInterface>hardware_interface/EffortJointInterface</hardwareInterface>
    </joint>
    <actuator name="right_close_motor">
      <hardwareInterface>hardware_interface/EffortJointInterface</hardwareInterface>
      <mechanicalReduction>1</mechanicalReduction>
    </actuator>
  </transmission>
</robot>

