<sdf version='1.6'>
  <model name='biped'>
    <link name='x-prism'>
      <pose frame=''>0 0 0.45 0 -0 0</pose>
      <inertial>
        <pose frame=''>0 0 0 0 -0 0</pose>
        <mass>1</mass>
        <inertia>
          <ixx>0.000166667</ixx>
          <ixy>0</ixy>
          <ixz>0</ixz>
          <iyy>0.000166667</iyy>
          <iyz>0</iyz>
          <izz>0.000166667</izz>
        </inertia>
      </inertial>
      <visual name='x-prism_visual'>
        <pose frame=''>0 0 0 0 -0 0</pose>
        <geometry>
          <box>
            <size>0.001 0.001 0.001</size>
          </box>
        </geometry>
      </visual>
    </link>
    <joint name='planx' type='prismatic'>
      <child>x-prism</child>
      <parent>world</parent>
      <axis>
        <xyz>1 0 0</xyz>
        <limit>
          <lower>-10</lower>
          <upper>50</upper>
          <effort>1000</effort>
          <velocity>10</velocity>
        </limit>
        <dynamics>
          <spring_reference>0</spring_reference>
          <spring_stiffness>0</spring_stiffness>
        </dynamics>
        <use_parent_model_frame>1</use_parent_model_frame>
      </axis>
    </joint>
    <link name='hip'>
      <pose frame=''>0 0 0.45 0 -0 0</pose>
      <inertial>
        <pose frame=''>0 0 0 0 -0 0</pose>
        <mass>3</mass>
        <inertia>
          <ixx>0.00585</ixx>
          <ixy>0</ixy>
          <ixz>0</ixz>
          <iyy>0.00585</iyy>
          <iyz>0</iyz>
          <izz>0.01125</izz>
        </inertia>
      </inertial>
      <collision name='hip_collision'>
        <pose frame=''>0 0 0 0 -0 0</pose>
        <geometry>
          <box>
            <size>0.3 0.15 0.03</size>
          </box>
        </geometry>
        <surface>
          <contact>
            <ode/>
          </contact>
          <friction>
            <ode/>
          </friction>
        </surface>
      </collision>
      <visual name='hip_visual'>
        <pose frame=''>0 0 0 0 -0 0</pose>
        <geometry>
          <box>
            <size>0.3 0.15 0.03</size>
          </box>
        </geometry>
        <material>
          <script>
            <name>Gazebo/Orange</name>
            <uri>file://media/materials/scripts/gazebo.material</uri>
          </script>
        </material>
      </visual>
      <gravity>1</gravity>
      <velocity_decay/>
    </link>
    <joint name='planz' type='prismatic'>
      <child>hip</child>
      <parent>x-prism</parent>
      <axis>
        <xyz>0 0 1</xyz>
        <limit>
          <lower>-10</lower>
          <upper>50</upper>
          <effort>1000</effort>
          <velocity>10</velocity>
        </limit>
        <dynamics>
          <spring_reference>0</spring_reference>
          <spring_stiffness>0</spring_stiffness>
        </dynamics>
        <use_parent_model_frame>1</use_parent_model_frame>
      </axis>
    </joint>
    <link name='leg_left_abad'>
      <pose frame=''>0 0 0.45 0 -0 0</pose>
      <inertial>
        <pose frame=''>0 0.09 0 0 -0 0</pose>
        <mass>1</mass>
        <inertia>
          <ixx>0.000841667</ixx>
          <ixy>0</ixy>
          <ixz>0</ixz>
          <iyy>0.00166667</iyy>
          <iyz>0</iyz>
          <izz>0.000841667</izz>
        </inertia>
      </inertial>
      <collision name='leg_left_abad_collision'>
        <pose frame=''>0 0.09 0 0 -0 0</pose>
        <geometry>
          <box>
            <size>0.1 0.01 0.1</size>
          </box>
        </geometry>
        <surface>
          <contact>
            <ode/>
          </contact>
          <friction>
            <ode>
              <mu>0.2</mu>
              <mu2>0.2</mu2>
            </ode>
          </friction>
        </surface>
      </collision>
      <visual name='leg_left_abad_visual'>
        <pose frame=''>0 0.09 0 0 -0 0</pose>
        <geometry>
          <box>
            <size>0.1 0.01 0.1</size>
          </box>
        </geometry>
        <material>
          <script>
            <name>Gazebo/Black</name>
            <uri>file://media/materials/scripts/gazebo.material</uri>
          </script>
        </material>
      </visual>
      <gravity>1</gravity>
      <velocity_decay/>
      <self_collide>1</self_collide>
    </link>
    <joint name='left_abad_joint' type='revolute'>
      <child>leg_left_abad</child>
      <parent>hip</parent>
      <axis>
        <xyz>1 0 0</xyz>
        <limit>
          <lower>-0.5236</lower>
          <upper>0.5236</upper>
          <effort>50</effort>
          <velocity>10</velocity>
        </limit>
        <dynamics>
          <damping>0.7</damping>
          <friction>0</friction>
          <spring_reference>0</spring_reference>
          <spring_stiffness>0</spring_stiffness>
        </dynamics>
        <use_parent_model_frame>1</use_parent_model_frame>
      </axis>
    </joint>
    <link name='leg_left_spring_rear'>
      <pose frame=''>0 0.115 0.45 0 0.196 0</pose>
      <inertial>
        <pose frame=''>0 0.015 0 0 -0 0</pose>
        <mass>1</mass>
        <inertia>
          <ixx>0.000841667</ixx>
          <ixy>0</ixy>
          <ixz>0</ixz>
          <iyy>0.00166667</iyy>
          <iyz>0</iyz>
          <izz>0.000841667</izz>
        </inertia>
      </inertial>
      <collision name='leg_left_spring_rear_collision'>
        <pose frame=''>0 0.015 0 0 -0 0</pose>
        <geometry>
          <box>
            <size>0.1 0.01 0.1</size>
          </box>
        </geometry>
      </collision>
      <visual name='leg_left_spring_rear_visual'>
        <pose frame=''>0 0.015 0 0 -0 0</pose>
        <geometry>
          <box>
            <size>0.1 0.01 0.1</size>
          </box>
        </geometry>
      </visual>
    </link>
    <joint name='left_spring_rear_joint' type='revolute'>
      <child>leg_left_spring_rear</child>
      <parent>leg_left_abad</parent>
      <axis>
        <xyz>0 1 0</xyz>
        <limit>
          <lower>-1e+16</lower>
          <upper>1e+16</upper>
        </limit>
        <dynamics>
          <spring_reference>0</spring_reference>
          <spring_stiffness>0</spring_stiffness>
        </dynamics>
        <use_parent_model_frame>1</use_parent_model_frame>
      </axis>
    </joint>
    <link name='leg_left_rear_top'>
      <pose frame=''>0 0.163 0.45 3.14159 -0.196007 -3.14159</pose>
      <inertial>
        <pose frame=''>0 0.019 0.112 0 -0 0</pose>
        <mass>0.15</mass>
        <inertia>
          <ixx>0.00084905</ixx>
          <ixy>0</ixy>
          <ixz>0</ixz>
          <iyy>0.00084905</iyy>
          <iyz>0</iyz>
          <izz>8.1e-06</izz>
        </inertia>
      </inertial>
      <collision name='leg_left_rear_top_collision'>
        <pose frame=''>0 0.019 0.112 0 -0 0</pose>
        <geometry>
          <box>
            <size>0.018 0.018 0.26</size>
          </box>
        </geometry>
        <surface>
          <contact>
            <ode/>
          </contact>
          <friction>
            <ode>
              <mu>0.2</mu>
              <mu2>0.2</mu2>
            </ode>
          </friction>
        </surface>
      </collision>
      <visual name='leg_left_rear_top_visual'>
        <pose frame=''>0 0.001 0.112 0 -0 0</pose>
        <geometry>
          <box>
            <size>0.018 0.018 0.26</size>
          </box>
        </geometry>
        <material>
          <script>
            <name>Gazebo/White</name>
            <uri>file://media/materials/scripts/gazebo.material</uri>
          </script>
        </material>
      </visual>
      <gravity>1</gravity>
      <velocity_decay/>
      <self_collide>1</self_collide>
    </link>
    <joint name='left_rear_joint' type='revolute'>
      <child>leg_left_rear_top</child>
      <parent>leg_left_spring_rear</parent>
      <axis>
        <xyz>0 1 0</xyz>
        <limit>
          <lower>-1.57</lower>
          <upper>1.57</upper>
          <effort>50</effort>
          <velocity>10</velocity>
        </limit>
        <dynamics>
          <damping>0.7</damping>
          <friction>0</friction>
          <spring_reference>0</spring_reference>
          <spring_stiffness>0</spring_stiffness>
        </dynamics>
        <use_parent_model_frame>1</use_parent_model_frame>
      </axis>
    </joint>
    <link name='leg_left_rear_bot'>
      <pose frame=''>-0.047131 0.153 0.212634 3.14159 0.196993 3.14159</pose>
      <inertial>
        <pose frame=''>0 0.001 0.120125 0 -0 0</pose>
        <mass>0.16</mass>
        <inertia>
          <ixx>0.00100749</ixx>
          <ixy>0</ixy>
          <ixz>0</ixz>
          <iyy>0.00100749</iyy>
          <iyz>-3.38813e-21</iyz>
          <izz>8.1e-06</izz>
        </inertia>
      </inertial>
      <collision name='leg_left_rear_bot_collision'>
        <pose frame=''>0 0.001 0.112 0 -0 0</pose>
        <geometry>
          <box>
            <size>0.018 0.018 0.26</size>
          </box>
        </geometry>
        <surface>
          <contact>
            <ode/>
          </contact>
          <friction>
            <ode>
              <mu>0.2</mu>
              <mu2>0.2</mu2>
            </ode>
          </friction>
        </surface>
      </collision>
      <collision name='leg_left_rear_bot_fixed_joint_lump__left_end_tip_collision_1'>
        <pose frame=''>0 0.001 0.242 0 -0 0</pose>
        <geometry>
          <sphere>
            <radius>0.009</radius>
          </sphere>
        </geometry>
        <surface>
          <contact>
            <ode/>
          </contact>
          <friction>
            <ode>
              <mu>1</mu>
              <mu2>1</mu2>
            </ode>
          </friction>
        </surface>
      </collision>
      <visual name='leg_left_rear_bot_visual'>
        <pose frame=''>0 0.001 0.112 0 -0 0</pose>
        <geometry>
          <box>
            <size>0.018 0.018 0.26</size>
          </box>
        </geometry>
        <material>
          <script>
            <name>Gazebo/White</name>
            <uri>file://media/materials/scripts/gazebo.material</uri>
          </script>
        </material>
      </visual>
      <visual name='leg_left_rear_bot_fixed_joint_lump__left_end_tip_visual_1'>
        <pose frame=''>0 0.001 0.242 0 -0 0</pose>
        <geometry>
          <sphere>
            <radius>0.009</radius>
          </sphere>
        </geometry>
        <material>
          <script>
            <name>Gazebo/Blue</name>
            <uri>file://media/materials/scripts/gazebo.material</uri>
          </script>
        </material>
      </visual>
      <velocity_decay/>
      <gravity>1</gravity>
      <velocity_decay/>
      <self_collide>1</self_collide>
    </link>
    <joint name='left_rear_joint2' type='revolute'>
      <child>leg_left_rear_bot</child>
      <parent>leg_left_rear_top</parent>
      <axis>
        <xyz>0 1 0</xyz>
        <limit>
          <lower>-1.57</lower>
          <upper>1.57</upper>
          <effort>50</effort>
          <velocity>10</velocity>
        </limit>
        <dynamics>
          <damping>0.7</damping>
          <friction>0</friction>
          <spring_reference>0</spring_reference>
          <spring_stiffness>0</spring_stiffness>
        </dynamics>
        <use_parent_model_frame>1</use_parent_model_frame>
      </axis>
    </joint>
    <link name='leg_left_front_bot'>
      <pose frame=''>-0.015032 0.163 0.051806 0 0.1956 0</pose>
      <inertial>
        <pose frame=''>0 0.019 0.112 0 -0 0</pose>
        <mass>0.15</mass>
        <inertia>
          <ixx>0.00084905</ixx>
          <ixy>0</ixy>
          <ixz>0</ixz>
          <iyy>0.00084905</iyy>
          <iyz>0</iyz>
          <izz>8.1e-06</izz>
        </inertia>
      </inertial>
      <visual name='leg_left_front_bot_visual'>
        <pose frame=''>0 0.019 0.112 0 -0 0</pose>
        <geometry>
          <box>
            <size>0.018 0.018 0.26</size>
          </box>
        </geometry>
        <material>
          <script>
            <name>Gazebo/White</name>
            <uri>file://media/materials/scripts/gazebo.material</uri>
          </script>
        </material>
      </visual>
      <gravity>1</gravity>
      <velocity_decay/>
      <self_collide>1</self_collide>
    </link>
    <joint name='left_close_joint' type='revolute'>
      <child>leg_left_front_bot</child>
      <parent>leg_left_rear_bot</parent>
      <axis>
        <xyz>0 1 0</xyz>
        <limit>
          <lower>-1e+16</lower>
          <upper>1e+16</upper>
        </limit>
        <dynamics>
          <damping>0.7</damping>
          <friction>0</friction>
          <spring_reference>0</spring_reference>
          <spring_stiffness>0</spring_stiffness>
        </dynamics>
        <use_parent_model_frame>1</use_parent_model_frame>
      </axis>
    </joint>
    <link name='leg_left_front_top'>
      <pose frame=''>0.032002 0.135 0.289191 0 -0.1964 0</pose>
      <inertial>
        <pose frame=''>0 0.019 0.082 0 -0 0</pose>
        <mass>0.15</mass>
        <inertia>
          <ixx>0.00050405</ixx>
          <ixy>0</ixy>
          <ixz>0</ixz>
          <iyy>0.00065405</iyy>
          <iyz>0</iyz>
          <izz>8.1e-06</izz>
        </inertia>
      </inertial>
      <collision name='leg_left_front_top_collision'>
        <pose frame=''>0 0.019 0.082 0 -0 0</pose>
        <geometry>
          <box>
            <size>0.018 0.018 0.2</size>
          </box>
        </geometry>
        <surface>
          <contact>
            <ode/>
          </contact>
          <friction>
            <ode>
              <mu>0.2</mu>
              <mu2>0.2</mu2>
            </ode>
          </friction>
        </surface>
      </collision>
      <visual name='leg_left_front_top_visual'>
        <pose frame=''>0 0.019 0.082 0 -0 0</pose>
        <geometry>
          <box>
            <size>0.018 0.018 0.2</size>
          </box>
        </geometry>
        <material>
          <script>
            <name>Gazebo/White</name>
            <uri>file://media/materials/scripts/gazebo.material</uri>
          </script>
        </material>
      </visual>
      <gravity>1</gravity>
      <velocity_decay/>
      <self_collide>1</self_collide>
    </link>
    <joint name='left_front_joint2' type='revolute'>
      <child>leg_left_front_top</child>
      <parent>leg_left_front_bot</parent>
      <axis>
        <xyz>0 1 0</xyz>
        <limit>
          <lower>-1.57</lower>
          <upper>1.57</upper>
          <effort>50</effort>
          <velocity>10</velocity>
        </limit>
        <dynamics>
          <damping>0.7</damping>
          <friction>0</friction>
          <spring_reference>0</spring_reference>
          <spring_stiffness>0</spring_stiffness>
        </dynamics>
        <use_parent_model_frame>1</use_parent_model_frame>
      </axis>
    </joint>
    <link name='leg_left_spring_front'>
      <pose frame=''>-1e-06 0.095 0.450038 3.14159 0.196393 3.14159</pose>
      <inertial>
        <pose frame=''>0 0.015 0 0 -0 0</pose>
        <mass>1</mass>
        <inertia>
          <ixx>0.000841667</ixx>
          <ixy>0</ixy>
          <ixz>0</ixz>
          <iyy>0.00166667</iyy>
          <iyz>0</iyz>
          <izz>0.000841667</izz>
        </inertia>
      </inertial>
      <collision name='leg_left_spring_front_collision'>
        <pose frame=''>0 0.015 0 0 -0 0</pose>
        <geometry>
          <box>
            <size>0.1 0.01 0.1</size>
          </box>
        </geometry>
      </collision>
      <visual name='leg_left_spring_front_visual'>
        <pose frame=''>0 0.015 0 0 -0 0</pose>
        <geometry>
          <box>
            <size>0.1 0.01 0.1</size>
          </box>
        </geometry>
      </visual>
    </link>
    <joint name='left_front_joint' type='revolute'>
      <child>leg_left_spring_front</child>
      <parent>leg_left_front_top</parent>
      <axis>
        <xyz>0 1 0</xyz>
        <limit>
          <lower>-1.57</lower>
          <upper>1.57</upper>
          <effort>50</effort>
          <velocity>10</velocity>
        </limit>
        <dynamics>
          <damping>0.7</damping>
          <friction>0</friction>
          <spring_reference>0</spring_reference>
          <spring_stiffness>0</spring_stiffness>
        </dynamics>
        <use_parent_model_frame>1</use_parent_model_frame>
      </axis>
    </joint>
    <link name='leg_right_abad'>
      <pose frame=''>0 0 0.45 0 -0 0</pose>
      <inertial>
        <pose frame=''>0 -0.09 0 0 -0 0</pose>
        <mass>1</mass>
        <inertia>
          <ixx>0.000841667</ixx>
          <ixy>0</ixy>
          <ixz>0</ixz>
          <iyy>0.00166667</iyy>
          <iyz>0</iyz>
          <izz>0.000841667</izz>
        </inertia>
      </inertial>
      <collision name='leg_right_abad_collision'>
        <pose frame=''>0 -0.09 0 0 -0 0</pose>
        <geometry>
          <box>
            <size>0.1 0.01 0.1</size>
          </box>
        </geometry>
        <surface>
          <contact>
            <ode/>
          </contact>
          <friction>
            <ode>
              <mu>0.2</mu>
              <mu2>0.2</mu2>
            </ode>
          </friction>
        </surface>
      </collision>
      <visual name='leg_right_abad_visual'>
        <pose frame=''>0 -0.09 0 0 -0 0</pose>
        <geometry>
          <box>
            <size>0.1 0.01 0.1</size>
          </box>
        </geometry>
        <material>
          <script>
            <name>Gazebo/Black</name>
            <uri>file://media/materials/scripts/gazebo.material</uri>
          </script>
        </material>
      </visual>
      <gravity>1</gravity>
      <velocity_decay/>
      <self_collide>1</self_collide>
    </link>
    <joint name='right_abad_joint' type='revolute'>
      <child>leg_right_abad</child>
      <parent>hip</parent>
      <axis>
        <xyz>1 0 0</xyz>
        <limit>
          <lower>-0.5236</lower>
          <upper>0.5236</upper>
          <effort>50</effort>
          <velocity>10</velocity>
        </limit>
        <dynamics>
          <damping>0.7</damping>
          <friction>0</friction>
          <spring_reference>0</spring_reference>
          <spring_stiffness>0</spring_stiffness>
        </dynamics>
        <use_parent_model_frame>1</use_parent_model_frame>
      </axis>
    </joint>
    <link name='leg_right_spring_rear'>
      <pose frame=''>0 -0.115 0.45 0 0.196 0</pose>
      <inertial>
        <pose frame=''>0 -0.015 0 0 -0 0</pose>
        <mass>1</mass>
        <inertia>
          <ixx>0.000841667</ixx>
          <ixy>0</ixy>
          <ixz>0</ixz>
          <iyy>0.00166667</iyy>
          <iyz>0</iyz>
          <izz>0.000841667</izz>
        </inertia>
      </inertial>
      <collision name='leg_right_spring_rear_collision'>
        <pose frame=''>0 -0.015 0 0 -0 0</pose>
        <geometry>
          <box>
            <size>0.1 0.01 0.1</size>
          </box>
        </geometry>
      </collision>
      <visual name='leg_right_spring_rear_visual'>
        <pose frame=''>0 -0.015 0 0 -0 0</pose>
        <geometry>
          <box>
            <size>0.1 0.01 0.1</size>
          </box>
        </geometry>
      </visual>
    </link>
    <joint name='right_spring_rear_joint' type='revolute'>
      <child>leg_right_spring_rear</child>
      <parent>leg_right_abad</parent>
      <axis>
        <xyz>0 1 0</xyz>
        <limit>
          <lower>-1e+16</lower>
          <upper>1e+16</upper>
        </limit>
        <dynamics>
          <spring_reference>0</spring_reference>
          <spring_stiffness>0</spring_stiffness>
        </dynamics>
        <use_parent_model_frame>1</use_parent_model_frame>
      </axis>
    </joint>
    <link name='leg_right_rear_top'>
      <pose frame=''>0 -0.163 0.45 3.14159 -0.196007 -3.14159</pose>
      <inertial>
        <pose frame=''>0 -0.019 0.112 0 -0 0</pose>
        <mass>0.15</mass>
        <inertia>
          <ixx>0.00084905</ixx>
          <ixy>0</ixy>
          <ixz>0</ixz>
          <iyy>0.00084905</iyy>
          <iyz>0</iyz>
          <izz>8.1e-06</izz>
        </inertia>
      </inertial>
      <collision name='leg_right_rear_top_collision'>
        <pose frame=''>0 -0.019 0.112 0 -0 0</pose>
        <geometry>
          <box>
            <size>0.018 0.018 0.26</size>
          </box>
        </geometry>
        <surface>
          <contact>
            <ode/>
          </contact>
          <friction>
            <ode>
              <mu>0.2</mu>
              <mu2>0.2</mu2>
            </ode>
          </friction>
        </surface>
      </collision>
      <visual name='leg_right_rear_top_visual'>
        <pose frame=''>0 -0.019 0.112 0 -0 0</pose>
        <geometry>
          <box>
            <size>0.018 0.018 0.26</size>
          </box>
        </geometry>
        <material>
          <script>
            <name>Gazebo/White</name>
            <uri>file://media/materials/scripts/gazebo.material</uri>
          </script>
        </material>
      </visual>
      <gravity>1</gravity>
      <velocity_decay/>
      <self_collide>1</self_collide>
    </link>
    <joint name='right_rear_joint' type='revolute'>
      <child>leg_right_rear_top</child>
      <parent>leg_right_spring_rear</parent>
      <axis>
        <xyz>0 1 0</xyz>
        <limit>
          <lower>-1.57</lower>
          <upper>1.57</upper>
          <effort>50</effort>
          <velocity>10</velocity>
        </limit>
        <dynamics>
          <damping>0.7</damping>
          <friction>0</friction>
          <spring_reference>0</spring_reference>
          <spring_stiffness>0</spring_stiffness>
        </dynamics>
        <use_parent_model_frame>1</use_parent_model_frame>
      </axis>
    </joint>
    <link name='leg_right_rear_bot'>
      <pose frame=''>-0.047131 -0.153 0.212634 3.14159 0.196993 3.14159</pose>
      <inertial>
        <pose frame=''>0 -0.001 0.112 0 -0 0</pose>
        <mass>0.15</mass>
        <inertia>
          <ixx>0.00084905</ixx>
          <ixy>0</ixy>
          <ixz>0</ixz>
          <iyy>0.00084905</iyy>
          <iyz>0</iyz>
          <izz>8.1e-06</izz>
        </inertia>
      </inertial>
      <visual name='leg_right_rear_bot_visual'>
        <pose frame=''>0 -0.001 0.112 0 -0 0</pose>
        <geometry>
          <box>
            <size>0.018 0.018 0.26</size>
          </box>
        </geometry>
        <material>
          <script>
            <name>Gazebo/White</name>
            <uri>file://media/materials/scripts/gazebo.material</uri>
          </script>
        </material>
      </visual>
      <gravity>1</gravity>
      <velocity_decay/>
      <self_collide>1</self_collide>
    </link>
    <joint name='right_rear_joint2' type='revolute'>
      <child>leg_right_rear_bot</child>
      <parent>leg_right_rear_top</parent>
      <axis>
        <xyz>0 1 0</xyz>
        <limit>
          <lower>-1.57</lower>
          <upper>1.57</upper>
          <effort>50</effort>
          <velocity>10</velocity>
        </limit>
        <dynamics>
          <damping>0.7</damping>
          <friction>0</friction>
          <spring_reference>0</spring_reference>
          <spring_stiffness>0</spring_stiffness>
        </dynamics>
        <use_parent_model_frame>1</use_parent_model_frame>
      </axis>
    </joint>
    <link name='leg_right_front_bot'>
      <pose frame=''>-0.015032 -0.163 0.051806 0 0.1956 0</pose>
      <inertial>
        <pose frame=''>0 -0.019 0.112 0 -0 0</pose>
        <mass>0.15</mass>
        <inertia>
          <ixx>0.00084905</ixx>
          <ixy>0</ixy>
          <ixz>0</ixz>
          <iyy>0.00084905</iyy>
          <iyz>0</iyz>
          <izz>8.1e-06</izz>
        </inertia>
      </inertial>
      <visual name='leg_right_front_bot_visual'>
        <pose frame=''>0 -0.019 0.112 0 -0 0</pose>
        <geometry>
          <box>
            <size>0.018 0.018 0.26</size>
          </box>
        </geometry>
        <material>
          <script>
            <name>Gazebo/White</name>
            <uri>file://media/materials/scripts/gazebo.material</uri>
          </script>
        </material>
      </visual>
      <gravity>1</gravity>
      <velocity_decay/>
      <self_collide>1</self_collide>
    </link>
    <joint name='right_close_joint' type='revolute'>
      <child>leg_right_front_bot</child>
      <parent>leg_right_rear_bot</parent>
      <axis>
        <xyz>0 1 0</xyz>
        <limit>
          <lower>-1e+16</lower>
          <upper>1e+16</upper>
        </limit>
        <dynamics>
          <damping>0.7</damping>
          <friction>0</friction>
          <spring_reference>0</spring_reference>
          <spring_stiffness>0</spring_stiffness>
        </dynamics>
        <use_parent_model_frame>1</use_parent_model_frame>
      </axis>
    </joint>
    <link name='leg_right_front_top'>
      <pose frame=''>0.032002 -0.135 0.289191 0 -0.1964 0</pose>
      <inertial>
        <pose frame=''>0 -0.019 0.082 0 -0 0</pose>
        <mass>0.15</mass>
        <inertia>
          <ixx>0.00050405</ixx>
          <ixy>0</ixy>
          <ixz>0</ixz>
          <iyy>0.00065405</iyy>
          <iyz>0</iyz>
          <izz>8.1e-06</izz>
        </inertia>
      </inertial>
      <collision name='leg_right_front_top_collision'>
        <pose frame=''>0 -0.019 0.082 0 -0 0</pose>
        <geometry>
          <box>
            <size>0.018 0.018 0.2</size>
          </box>
        </geometry>
        <surface>
          <contact>
            <ode/>
          </contact>
          <friction>
            <ode>
              <mu>0.2</mu>
              <mu2>0.2</mu2>
            </ode>
          </friction>
        </surface>
      </collision>
      <visual name='leg_right_front_top_visual'>
        <pose frame=''>0 -0.019 0.082 0 -0 0</pose>
        <geometry>
          <box>
            <size>0.018 0.018 0.2</size>
          </box>
        </geometry>
        <material>
          <script>
            <name>Gazebo/White</name>
            <uri>file://media/materials/scripts/gazebo.material</uri>
          </script>
        </material>
      </visual>
      <gravity>1</gravity>
      <velocity_decay/>
      <self_collide>1</self_collide>
    </link>
    <joint name='right_front_joint2' type='revolute'>
      <child>leg_right_front_top</child>
      <parent>leg_right_front_bot</parent>
      <axis>
        <xyz>0 1 0</xyz>
        <limit>
          <lower>-1.57</lower>
          <upper>1.57</upper>
          <effort>50</effort>
          <velocity>10</velocity>
        </limit>
        <dynamics>
          <damping>0.7</damping>
          <friction>0</friction>
          <spring_reference>0</spring_reference>
          <spring_stiffness>0</spring_stiffness>
        </dynamics>
        <use_parent_model_frame>1</use_parent_model_frame>
      </axis>
    </joint>
    <link name='leg_right_spring_front'>
      <pose frame=''>-1e-06 -0.095 0.450038 3.14159 0.196393 3.14159</pose>
      <inertial>
        <pose frame=''>0 -0.015 0 0 -0 0</pose>
        <mass>1</mass>
        <inertia>
          <ixx>0.000841667</ixx>
          <ixy>0</ixy>
          <ixz>0</ixz>
          <iyy>0.00166667</iyy>
          <iyz>0</iyz>
          <izz>0.000841667</izz>
        </inertia>
      </inertial>
      <collision name='leg_right_spring_front_collision'>
        <pose frame=''>0 -0.015 0 0 -0 0</pose>
        <geometry>
          <box>
            <size>0.1 0.01 0.1</size>
          </box>
        </geometry>
      </collision>
      <visual name='leg_right_spring_front_visual'>
        <pose frame=''>0 -0.015 0 0 -0 0</pose>
        <geometry>
          <box>
            <size>0.1 0.01 0.1</size>
          </box>
        </geometry>
      </visual>
    </link>
    <joint name='right_front_joint' type='revolute'>
      <child>leg_right_spring_front</child>
      <parent>leg_right_front_top</parent>
      <axis>
        <xyz>0 1 0</xyz>
        <limit>
          <lower>-1.57</lower>
          <upper>1.57</upper>
          <effort>50</effort>
          <velocity>10</velocity>
        </limit>
        <dynamics>
          <damping>0.7</damping>
          <friction>0</friction>
          <spring_reference>0</spring_reference>
          <spring_stiffness>0</spring_stiffness>
        </dynamics>
        <use_parent_model_frame>1</use_parent_model_frame>
      </axis>
    </joint>
    <link name='right_end_tip'>
      <pose frame=''>0.000234 -0.154 -0.024686 3.14159 0.196993 3.14159</pose>
      <inertial>
        <pose frame=''>0 0 0.1 0 -0 0</pose>
        <mass>0.01875</mass>
        <inertia>
          <ixx>1.61312e-05</ixx>
          <ixy>0</ixy>
          <ixz>0</ixz>
          <iyy>1.61312e-05</iyy>
          <iyz>0</iyz>
          <izz>1.0125e-06</izz>
        </inertia>
      </inertial>
      <collision name='right_end_tip_collision'>
        <pose frame=''>0 0 0.01 3.14159 1.57079 3.14159</pose>
        <geometry>
          <box>
            <size>0.009 0.018 0.1</size>
          </box>
        </geometry>
        <surface>
          <contact>
            <ode/>
          </contact>
          <friction>
            <ode>
              <mu>1</mu>
              <mu2>1</mu2>
            </ode>
          </friction>
        </surface>
      </collision>
      <visual name='right_end_tip_visual'>
        <pose frame=''>0 0 0.01 3.14159 1.57079 3.14159</pose>
        <geometry>
          <box>
            <size>0.009 0.018 0.1</size>
          </box>
        </geometry>
        <material>
          <script>
            <name>Gazebo/Blue</name>
            <uri>file://media/materials/scripts/gazebo.material</uri>
          </script>
        </material>
      </visual>
      <gravity>1</gravity>
      <velocity_decay/>
      <self_collide>1</self_collide>
    </link>
    <joint name='right_end_joint' type='revolute'>
      <child>right_end_tip</child>
      <parent>leg_right_rear_bot</parent>
      <axis>
        <xyz>0 1 0</xyz>
        <limit>
          <lower>-1e+16</lower>
          <upper>1e+16</upper>
        </limit>
        <dynamics>
          <spring_reference>0</spring_reference>
          <spring_stiffness>0</spring_stiffness>
        </dynamics>
        <use_parent_model_frame>1</use_parent_model_frame>
      </axis>
    </joint>
    <joint name='right_spring_front_joint' type='revolute'>
      <child>leg_right_abad</child>
      <parent>leg_right_spring_front</parent>
      <axis>
        <xyz>0 1 0</xyz>
        <limit>
          <lower>-1e+16</lower>
          <upper>1e+16</upper>
        </limit>
        <dynamics>
          <damping>0.7</damping>
          <friction>0</friction>
          <spring_reference>0</spring_reference>
          <spring_stiffness>0</spring_stiffness>
        </dynamics>
        <use_parent_model_frame>1</use_parent_model_frame>
      </axis>
    </joint>
    <joint name='left_spring_front_joint' type='revolute'>
      <child>leg_left_abad</child>
      <parent>leg_left_spring_front</parent>
      <axis>
        <xyz>0 1 0</xyz>
        <limit>
          <lower>-1e+16</lower>
          <upper>1e+16</upper>
        </limit>
        <dynamics>
          <damping>0.7</damping>
          <friction>0</friction>
          <spring_reference>0</spring_reference>
          <spring_stiffness>0</spring_stiffness>
        </dynamics>
        <use_parent_model_frame>1</use_parent_model_frame>
      </axis>
    </joint>
    <plugin name='gazebo_ros_control' filename='libgazebo_ros_control.so'>
      <robotNamespace>/biped2</robotNamespace>
      <robotSimType>biped2_sim_hardware/BipedHWSim</robotSimType>
    </plugin>
    <plugin name='left_knee_joint_torsional_spring' filename='libgazebo_joint_torsional_spring.so'>
      <kx>160</kx>
      <set_point>0.0</set_point>
      <joint>left_front_joint</joint>
    </plugin>
    <plugin name='left_knee_joint_torsional_spring2' filename='libgazebo_joint_torsional_spring.so'>
      <kx>160</kx>
      <set_point>0.0</set_point>
      <joint>left_rear_joint</joint>
    </plugin>
    <plugin name='right_knee_joint_torsional_spring' filename='libgazebo_joint_torsional_spring.so'>
      <kx>160</kx>
      <set_point>0.0</set_point>
      <joint>right_front_joint</joint>
    </plugin>
    <static>0</static>
    <plugin name='right_knee_joint_torsional_spring2' filename='libgazebo_joint_torsional_spring.so'>
      <kx>160</kx>
      <set_point>0.0</set_point>
      <joint>right_rear_joint</joint>
    </plugin>
  </model>
</sdf>
